<?xml version="1.0" ?>
<!-- =================================================================================== -->
<!-- |    This document was autogenerated by xacro from /home/andrej/ws/code/repos/lunalab_summit_xl_gen/lunalab_summit_xl_gen_description/urdf/lunalab_summit_xl_gen.urdf.xacro | -->
<!-- |    EDITING THIS FILE BY HAND IS NOT RECOMMENDED                                 | -->
<!-- =================================================================================== -->
<!-- URDF for Summit XL-GEN (LunaLab variant) -->
<robot name="lunalab_summit_xl_gen">
  <!-- Sensors -->
  <!-- <xacro:include filename="$(find lunalab_summit_xl_gen_description)/urdf/lunalab_summit_xl_sensors.xacro"/> -->
  <!-- Miscellaneous -->
  <!-- <xacro:include filename="$(find lunalab_summit_xl_gen_description)/urdf/lunalab_summit_xl_misc.xacro"/> -->
  <link name="robot_summit_xl_base_footprint">
  </link>
  <joint name="robot_summit_xl_base_footprint_joint" type="fixed">
    <origin rpy="0 0 0" xyz="0 0 0.11"/>
    <parent link="robot_summit_xl_base_footprint"/>
    <child link="robot_summit_xl_base_link"/>
  </joint>
  <link name="robot_summit_xl_base_link">
    <inertial>
      <mass value="25.0"/>
      <origin xyz="0 0 0"/>
      <inertia ixx="1.391" ixy="0.004" ixz="0.0" iyy="6.853" iyz="0.0" izz="6.125"/>
    </inertial>
    <visual>
      <origin rpy="0 0 0" xyz="0 0 0"/>
      <geometry>
        <mesh filename="package://lunalab_summit_xl_gen_description/meshes/summit_xl/visual/summit_xl_chassis.dae"/>
      </geometry>
    </visual>
    <collision>
      <origin rpy="0 0 0 " xyz="0 0 0"/>
      <geometry>
        <mesh filename="package://lunalab_summit_xl_gen_description/meshes/summit_xl/collision/summit_xl_chassis.stl"/>
      </geometry>
    </collision>
  </link>
  <link name="robot_summit_xl_base_docking_contact_link">
  </link>
  <joint name="robot_summit_xl_base_docking_joint" type="fixed">
    <origin rpy="0 0 0 " xyz="0.284 0.012 0.068"/>
    <parent link="robot_summit_xl_base_link"/>
    <child link="robot_summit_xl_base_docking_contact_link"/>
  </joint>
  <gazebo reference="robot_summit_xl_base_link">
    <visual>
      <material>
        <diffuse>1 1 1 1</diffuse>
        <specular>1 1 1 1</specular>
        <pbr>
          <metal>
            <albedo_map>package://lunalab_summit_xl_gen_description/materials/textures/summit_xl/chassis_albedo.png</albedo_map>
            <roughness_map>package://lunalab_summit_xl_gen_description/materials/textures/summit_xl/chassis_roughness.png</roughness_map>
            <metalness_map>package://lunalab_summit_xl_gen_description/materials/textures/summit_xl/chassis_metalness.png</metalness_map>
          </metal>
        </pbr>
      </material>
    </visual>
  </gazebo>
  <joint name="robot_summit_xl_front_left_wheel_joint" type="continuous">
    <parent link="robot_summit_xl_base_link"/>
    <child link="robot_summit_xl_front_left_wheel"/>
    <origin rpy="0 0 0" xyz="0.229 0.235 0.0"/>
    <axis rpy="0 0 0" xyz="0 1 0"/>
    <limit effort="100" velocity="100"/>
    <dynamics damping="0.035" friction="0.0005"/>
  </joint>
  <link name="robot_summit_xl_front_left_wheel">
    <visual>
      <origin rpy="0 0 0" xyz="0 0 0"/>
      <geometry>
        <mesh filename="package://lunalab_summit_xl_gen_description/meshes/summit_xl/visual/rubber_wheel_left.dae"/>
      </geometry>
    </visual>
    <collision>
      <origin rpy="1.5707963267948966 0 0" xyz="0 0 0"/>
      <geometry>
        <cylinder length="0.15" radius="0.11"/>
      </geometry>
    </collision>
    <inertial>
      <mass value="6.5"/>
      <origin xyz="0 0 0"/>
      <inertia ixx="0.031849999999999996" ixy="0" ixz="0" iyy="0.039325" iyz="0" izz="0.031849999999999996"/>
    </inertial>
  </link>
  <transmission name="robot_summit_xl_front_left_wheel_joint_trans">
    <type>transmission_interface/SimpleTransmission</type>
    <joint name="robot_summit_xl_front_left_wheel_joint">
      <hardwareInterface>hardware_interface/VelocityJointInterface</hardwareInterface>
    </joint>
    <actuator name="robot_summit_xl_front_left_wheel_joint_actuator">
      <mechanicalReduction>1</mechanicalReduction>
      <motorTorqueConstant>20</motorTorqueConstant>
    </actuator>
  </transmission>
  <gazebo reference="robot_summit_xl_front_left_wheel">
    <mu1 value="1.9"/>
    <mu2 value="1.7"/>
    <fdir1 value="1 0 0"/>
  </gazebo>
  <gazebo reference="robot_summit_xl_front_left_wheel">
    <visual>
      <material>
        <diffuse>1 1 1 1</diffuse>
        <specular>1 1 1 1</specular>
        <pbr>
          <metal>
            <albedo_map>package://lunalab_summit_xl_gen_description/materials/textures/summit_xl/rubber_wheel_albedo.png</albedo_map>
            <normal_map>package://lunalab_summit_xl_gen_description/materials/textures/summit_xl/rubber_wheel_normal.png</normal_map>
            <roughness_map>package://lunalab_summit_xl_gen_description/materials/textures/summit_xl/rubber_wheel_roughness.png</roughness_map>
            <metalness_map>package://lunalab_summit_xl_gen_description/materials/textures/summit_xl/rubber_wheel_metalness.png</metalness_map>
          </metal>
        </pbr>
      </material>
    </visual>
  </gazebo>
  <joint name="robot_summit_xl_back_left_wheel_joint" type="continuous">
    <parent link="robot_summit_xl_base_link"/>
    <child link="robot_summit_xl_back_left_wheel"/>
    <origin rpy="0 0 0" xyz="-0.229 0.235 0.0"/>
    <axis rpy="0 0 0" xyz="0 1 0"/>
    <limit effort="100" velocity="100"/>
    <dynamics damping="0.035" friction="0.0005"/>
  </joint>
  <link name="robot_summit_xl_back_left_wheel">
    <visual>
      <origin rpy="0 0 0" xyz="0 0 0"/>
      <geometry>
        <mesh filename="package://lunalab_summit_xl_gen_description/meshes/summit_xl/visual/rubber_wheel_left.dae"/>
      </geometry>
    </visual>
    <collision>
      <origin rpy="1.5707963267948966 0 0" xyz="0 0 0"/>
      <geometry>
        <cylinder length="0.15" radius="0.11"/>
      </geometry>
    </collision>
    <inertial>
      <mass value="6.5"/>
      <origin xyz="0 0 0"/>
      <inertia ixx="0.031849999999999996" ixy="0" ixz="0" iyy="0.039325" iyz="0" izz="0.031849999999999996"/>
    </inertial>
  </link>
  <transmission name="robot_summit_xl_back_left_wheel_joint_trans">
    <type>transmission_interface/SimpleTransmission</type>
    <joint name="robot_summit_xl_back_left_wheel_joint">
      <hardwareInterface>hardware_interface/VelocityJointInterface</hardwareInterface>
    </joint>
    <actuator name="robot_summit_xl_back_left_wheel_joint_actuator">
      <mechanicalReduction>1</mechanicalReduction>
      <motorTorqueConstant>20</motorTorqueConstant>
    </actuator>
  </transmission>
  <gazebo reference="robot_summit_xl_back_left_wheel">
    <mu1 value="1.9"/>
    <mu2 value="1.7"/>
    <fdir1 value="1 0 0"/>
  </gazebo>
  <gazebo reference="robot_summit_xl_back_left_wheel">
    <visual>
      <material>
        <diffuse>1 1 1 1</diffuse>
        <specular>1 1 1 1</specular>
        <pbr>
          <metal>
            <albedo_map>package://lunalab_summit_xl_gen_description/materials/textures/summit_xl/rubber_wheel_albedo.png</albedo_map>
            <normal_map>package://lunalab_summit_xl_gen_description/materials/textures/summit_xl/rubber_wheel_normal.png</normal_map>
            <roughness_map>package://lunalab_summit_xl_gen_description/materials/textures/summit_xl/rubber_wheel_roughness.png</roughness_map>
            <metalness_map>package://lunalab_summit_xl_gen_description/materials/textures/summit_xl/rubber_wheel_metalness.png</metalness_map>
          </metal>
        </pbr>
      </material>
    </visual>
  </gazebo>
  <joint name="robot_summit_xl_front_right_wheel_joint" type="continuous">
    <parent link="robot_summit_xl_base_link"/>
    <child link="robot_summit_xl_front_right_wheel"/>
    <origin rpy="0 0 0" xyz="0.229 -0.235 0.0"/>
    <axis rpy="0 0 0" xyz="0 1 0"/>
    <limit effort="100" velocity="100"/>
    <dynamics damping="0.035" friction="0.0005"/>
  </joint>
  <link name="robot_summit_xl_front_right_wheel">
    <visual>
      <origin rpy="0 0 0" xyz="0 0 0"/>
      <geometry>
        <mesh filename="package://lunalab_summit_xl_gen_description/meshes/summit_xl/visual/rubber_wheel_right.dae"/>
      </geometry>
    </visual>
    <collision>
      <origin rpy="1.5707963267948966 0 0" xyz="0 0 0"/>
      <geometry>
        <cylinder length="0.15" radius="0.11"/>
      </geometry>
    </collision>
    <inertial>
      <mass value="6.5"/>
      <origin xyz="0 0 0"/>
      <inertia ixx="0.031849999999999996" ixy="0" ixz="0" iyy="0.039325" iyz="0" izz="0.031849999999999996"/>
    </inertial>
  </link>
  <transmission name="robot_summit_xl_front_right_wheel_joint_trans">
    <type>transmission_interface/SimpleTransmission</type>
    <joint name="robot_summit_xl_front_right_wheel_joint">
      <hardwareInterface>hardware_interface/VelocityJointInterface</hardwareInterface>
    </joint>
    <actuator name="robot_summit_xl_front_right_wheel_joint_actuator">
      <mechanicalReduction>1</mechanicalReduction>
      <motorTorqueConstant>20</motorTorqueConstant>
    </actuator>
  </transmission>
  <gazebo reference="robot_summit_xl_front_right_wheel">
    <mu1 value="1.9"/>
    <mu2 value="1.7"/>
    <fdir1 value="1 0 0"/>
  </gazebo>
  <gazebo reference="robot_summit_xl_front_right_wheel">
    <visual>
      <material>
        <diffuse>1 1 1 1</diffuse>
        <specular>1 1 1 1</specular>
        <pbr>
          <metal>
            <albedo_map>package://lunalab_summit_xl_gen_description/materials/textures/summit_xl/rubber_wheel_albedo.png</albedo_map>
            <normal_map>package://lunalab_summit_xl_gen_description/materials/textures/summit_xl/rubber_wheel_normal.png</normal_map>
            <roughness_map>package://lunalab_summit_xl_gen_description/materials/textures/summit_xl/rubber_wheel_roughness.png</roughness_map>
            <metalness_map>package://lunalab_summit_xl_gen_description/materials/textures/summit_xl/rubber_wheel_metalness.png</metalness_map>
          </metal>
        </pbr>
      </material>
    </visual>
  </gazebo>
  <joint name="robot_summit_xl_back_right_wheel_joint" type="continuous">
    <parent link="robot_summit_xl_base_link"/>
    <child link="robot_summit_xl_back_right_wheel"/>
    <origin rpy="0 0 0" xyz="-0.229 -0.235 0.0"/>
    <axis rpy="0 0 0" xyz="0 1 0"/>
    <limit effort="100" velocity="100"/>
    <dynamics damping="0.035" friction="0.0005"/>
  </joint>
  <link name="robot_summit_xl_back_right_wheel">
    <visual>
      <origin rpy="0 0 0" xyz="0 0 0"/>
      <geometry>
        <mesh filename="package://lunalab_summit_xl_gen_description/meshes/summit_xl/visual/rubber_wheel_right.dae"/>
      </geometry>
    </visual>
    <collision>
      <origin rpy="1.5707963267948966 0 0" xyz="0 0 0"/>
      <geometry>
        <cylinder length="0.15" radius="0.11"/>
      </geometry>
    </collision>
    <inertial>
      <mass value="6.5"/>
      <origin xyz="0 0 0"/>
      <inertia ixx="0.031849999999999996" ixy="0" ixz="0" iyy="0.039325" iyz="0" izz="0.031849999999999996"/>
    </inertial>
  </link>
  <transmission name="robot_summit_xl_back_right_wheel_joint_trans">
    <type>transmission_interface/SimpleTransmission</type>
    <joint name="robot_summit_xl_back_right_wheel_joint">
      <hardwareInterface>hardware_interface/VelocityJointInterface</hardwareInterface>
    </joint>
    <actuator name="robot_summit_xl_back_right_wheel_joint_actuator">
      <mechanicalReduction>1</mechanicalReduction>
      <motorTorqueConstant>20</motorTorqueConstant>
    </actuator>
  </transmission>
  <gazebo reference="robot_summit_xl_back_right_wheel">
    <mu1 value="1.9"/>
    <mu2 value="1.7"/>
    <fdir1 value="1 0 0"/>
  </gazebo>
  <gazebo reference="robot_summit_xl_back_right_wheel">
    <visual>
      <material>
        <diffuse>1 1 1 1</diffuse>
        <specular>1 1 1 1</specular>
        <pbr>
          <metal>
            <albedo_map>package://lunalab_summit_xl_gen_description/materials/textures/summit_xl/rubber_wheel_albedo.png</albedo_map>
            <normal_map>package://lunalab_summit_xl_gen_description/materials/textures/summit_xl/rubber_wheel_normal.png</normal_map>
            <roughness_map>package://lunalab_summit_xl_gen_description/materials/textures/summit_xl/rubber_wheel_roughness.png</roughness_map>
            <metalness_map>package://lunalab_summit_xl_gen_description/materials/textures/summit_xl/rubber_wheel_metalness.png</metalness_map>
          </metal>
        </pbr>
      </material>
    </visual>
  </gazebo>
  <ros2_control name="SummitXlSystem" type="system">
    <hardware>
      <plugin>ign_ros2_control/IgnitionSystem</plugin>
    </hardware>
    <joint name="robot_summit_xl_front_left_wheel_joint">
      <param name="initial_position">0</param>
      <state_interface name="position"/>
      <state_interface name="velocity"/>
      <state_interface name="effort"/>
    </joint>
    <joint name="robot_summit_xl_back_left_wheel_joint">
      <param name="initial_position">0</param>
      <state_interface name="position"/>
      <state_interface name="velocity"/>
      <state_interface name="effort"/>
    </joint>
    <joint name="robot_summit_xl_front_right_wheel_joint">
      <param name="initial_position">0</param>
      <state_interface name="position"/>
      <state_interface name="velocity"/>
      <state_interface name="effort"/>
    </joint>
    <joint name="robot_summit_xl_back_right_wheel_joint">
      <param name="initial_position">0</param>
      <state_interface name="position"/>
      <state_interface name="velocity"/>
      <state_interface name="effort"/>
    </joint>
  </ros2_control>
  <gazebo>
    <plugin filename="ignition-gazebo-diff-drive-system" name="ignition::gazebo::systems::DiffDrive">
      <left_joint>robot_summit_xl_front_left_wheel_joint</left_joint>
      <left_joint>robot_summit_xl_back_left_wheel_joint</left_joint>
      <right_joint>robot_summit_xl_front_right_wheel_joint</right_joint>
      <right_joint>robot_summit_xl_back_right_wheel_joint</right_joint>
      <wheel_separation>0.47</wheel_separation>
      <wheel_radius>0.11</wheel_radius>
    </plugin>
  </gazebo>
  <link name="robot_j2s7s300_link_base">
    <visual>
      <geometry>
        <mesh filename="package://lunalab_summit_xl_gen_description/meshes/kinova/visual/base.dae"/>
      </geometry>
    </visual>
    <collision>
      <geometry>
        <mesh filename="package://lunalab_summit_xl_gen_description/meshes/kinova/collision/base.stl"/>
      </geometry>
    </collision>
    <inertial>
      <mass value="0.46784"/>
      <origin rpy="0 0 0" xyz="0 0 0.1255"/>
      <inertia ixx="0.0009512746666666666" ixy="0" ixz="0" iyy="0.0009512746666666666" iyz="0" izz="0.00037427200000000004"/>
    </inertial>
  </link>
  <gazebo reference="robot_j2s7s300_link_base">
    <mu1 value="0.9"/>
    <mu2 value="0.9"/>
  </gazebo>
  <gazebo reference="robot_j2s7s300_link_base">
    <visual>
      <material>
        <diffuse>1 1 1 1</diffuse>
        <specular>1 1 1 1</specular>
        <pbr>
          <metal>
            <albedo_map>package://lunalab_summit_xl_gen_description/materials/textures/kinova/kinova_gen2_albedo.png</albedo_map>
            <roughness_map>package://lunalab_summit_xl_gen_description/materials/textures/kinova/kinova_gen2_roughness.png</roughness_map>
            <metalness_map>package://lunalab_summit_xl_gen_description/materials/textures/kinova/kinova_gen2_metalness.png</metalness_map>
          </metal>
        </pbr>
      </material>
    </visual>
  </gazebo>
  <joint name="robot_j2s7s300_joint_base" type="fixed">
    <parent link="robot_summit_xl_base_link"/>
    <child link="robot_j2s7s300_link_base"/>
    <axis xyz="0 0 0"/>
    <origin rpy="0.0 0.0 0.0" xyz="0.204 0.0 0.11"/>
    <dynamics damping="0.0" friction="0.0"/>
    <safety_controller k_position="20" k_velocity="0.0" soft_lower_limit="0.17453293" soft_upper_limit="-0.17453293"/>
  </joint>
  <link name="robot_j2s7s300_link_1">
    <visual>
      <geometry>
        <mesh filename="package://lunalab_summit_xl_gen_description/meshes/kinova/visual/shoulder.dae"/>
      </geometry>
    </visual>
    <collision>
      <geometry>
        <mesh filename="package://lunalab_summit_xl_gen_description/meshes/kinova/collision/shoulder.stl"/>
      </geometry>
    </collision>
    <inertial>
      <mass value="0.7477"/>
      <origin xyz="0 -0.002 -0.0605"/>
      <inertia ixx="0.0015203233333333334" ixy="0" ixz="0" iyy="0.0015203233333333334" iyz="0" izz="0.00059816"/>
    </inertial>
  </link>
  <gazebo reference="robot_j2s7s300_link_1">
    <mu1 value="0.9"/>
    <mu2 value="0.9"/>
  </gazebo>
  <gazebo reference="robot_j2s7s300_link_1">
    <visual>
      <material>
        <diffuse>1 1 1 1</diffuse>
        <specular>1 1 1 1</specular>
        <pbr>
          <metal>
            <albedo_map>package://lunalab_summit_xl_gen_description/materials/textures/kinova/kinova_gen2_albedo.png</albedo_map>
            <roughness_map>package://lunalab_summit_xl_gen_description/materials/textures/kinova/kinova_gen2_roughness.png</roughness_map>
            <metalness_map>package://lunalab_summit_xl_gen_description/materials/textures/kinova/kinova_gen2_metalness.png</metalness_map>
          </metal>
        </pbr>
      </material>
    </visual>
  </gazebo>
  <joint name="robot_j2s7s300_joint_1" type="revolute">
    <parent link="robot_j2s7s300_link_base"/>
    <child link="robot_j2s7s300_link_1"/>
    <axis xyz="0 0 1"/>
    <limit effort="40" lower="-174.04423300887453" upper="174.04423300887453" velocity="0.6283185307179586"/>
    <origin rpy="0 3.141592653589793 0" xyz="0 0 0.15675"/>
    <dynamics damping="15.0" friction="0.5"/>
    <safety_controller k_position="20" k_velocity="0.0" soft_lower_limit="-173.86970007887453" soft_upper_limit="173.86970007887453"/>
  </joint>
  <transmission name="robot_j2s7s300_joint_1_trans">
    <type>transmission_interface/SimpleTransmission</type>
    <joint name="robot_j2s7s300_joint_1">
      <hardwareInterface>hardware_interface/EffortJointInterface</hardwareInterface>
    </joint>
    <actuator name="robot_j2s7s300_joint_1_actuator">
      <mechanicalReduction>160</mechanicalReduction>
    </actuator>
  </transmission>
  <link name="robot_j2s7s300_link_2">
    <visual>
      <geometry>
        <mesh filename="package://lunalab_summit_xl_gen_description/meshes/kinova/visual/arm_half_1.dae"/>
      </geometry>
    </visual>
    <collision>
      <geometry>
        <mesh filename="package://lunalab_summit_xl_gen_description/meshes/kinova/collision/arm_half_1.stl"/>
      </geometry>
    </collision>
    <inertial>
      <mass value="0.8447"/>
      <origin xyz="0 -0.103563213 0"/>
      <inertia ixx="0.0024707475" ixy="0" ixz="0" iyy="0.000380115" iyz="0" izz="0.0024707475"/>
    </inertial>
  </link>
  <gazebo reference="robot_j2s7s300_link_2">
    <mu1 value="0.9"/>
    <mu2 value="0.9"/>
  </gazebo>
  <gazebo reference="robot_j2s7s300_link_2">
    <visual>
      <material>
        <diffuse>1 1 1 1</diffuse>
        <specular>1 1 1 1</specular>
        <pbr>
          <metal>
            <albedo_map>package://lunalab_summit_xl_gen_description/materials/textures/kinova/kinova_gen2_albedo.png</albedo_map>
            <roughness_map>package://lunalab_summit_xl_gen_description/materials/textures/kinova/kinova_gen2_roughness.png</roughness_map>
            <metalness_map>package://lunalab_summit_xl_gen_description/materials/textures/kinova/kinova_gen2_metalness.png</metalness_map>
          </metal>
        </pbr>
      </material>
    </visual>
  </gazebo>
  <joint name="robot_j2s7s300_joint_2" type="revolute">
    <parent link="robot_j2s7s300_link_1"/>
    <child link="robot_j2s7s300_link_2"/>
    <axis xyz="0 0 1"/>
    <limit effort="40" lower="0.8203047484373349" upper="5.462880558742251" velocity="0.6283185307179586"/>
    <origin rpy="-1.5707963267948966 0 3.141592653589793" xyz="0 0.0016 -0.11875"/>
    <dynamics damping="16.0" friction="0.9"/>
    <safety_controller k_position="20" k_velocity="0.0" soft_lower_limit="0.994837678437335" soft_upper_limit="5.288347628742251"/>
  </joint>
  <transmission name="robot_j2s7s300_joint_2_trans">
    <type>transmission_interface/SimpleTransmission</type>
    <joint name="robot_j2s7s300_joint_2">
      <hardwareInterface>hardware_interface/EffortJointInterface</hardwareInterface>
    </joint>
    <actuator name="robot_j2s7s300_joint_2_actuator">
      <mechanicalReduction>160</mechanicalReduction>
    </actuator>
  </transmission>
  <link name="robot_j2s7s300_link_3">
    <visual>
      <geometry>
        <mesh filename="package://lunalab_summit_xl_gen_description/meshes/kinova/visual/arm_half_2.dae"/>
      </geometry>
    </visual>
    <collision>
      <geometry>
        <mesh filename="package://lunalab_summit_xl_gen_description/meshes/kinova/collision/arm_half_2.stl"/>
      </geometry>
    </collision>
    <inertial>
      <mass value="0.8447"/>
      <origin xyz="0 0 -0.1022447445"/>
      <inertia ixx="0.0024707475" ixy="0" ixz="0" iyy="0.0024707475" iyz="0" izz="0.000380115"/>
    </inertial>
  </link>
  <gazebo reference="robot_j2s7s300_link_3">
    <mu1 value="0.9"/>
    <mu2 value="0.9"/>
  </gazebo>
  <gazebo reference="robot_j2s7s300_link_3">
    <visual>
      <material>
        <diffuse>1 1 1 1</diffuse>
        <specular>1 1 1 1</specular>
        <pbr>
          <metal>
            <albedo_map>package://lunalab_summit_xl_gen_description/materials/textures/kinova/kinova_gen2_albedo.png</albedo_map>
            <roughness_map>package://lunalab_summit_xl_gen_description/materials/textures/kinova/kinova_gen2_roughness.png</roughness_map>
            <metalness_map>package://lunalab_summit_xl_gen_description/materials/textures/kinova/kinova_gen2_metalness.png</metalness_map>
          </metal>
        </pbr>
      </material>
    </visual>
  </gazebo>
  <joint name="robot_j2s7s300_joint_3" type="revolute">
    <parent link="robot_j2s7s300_link_2"/>
    <child link="robot_j2s7s300_link_3"/>
    <axis xyz="0 0 1"/>
    <limit effort="40" lower="-174.04423300887453" upper="174.04423300887453" velocity="0.6283185307179586"/>
    <origin rpy="-1.5707963267948966 0 0" xyz="0 -0.205 0"/>
    <dynamics damping="12.0" friction="0.8"/>
    <safety_controller k_position="20" k_velocity="0.0" soft_lower_limit="-173.86970007887453" soft_upper_limit="173.86970007887453"/>
  </joint>
  <transmission name="robot_j2s7s300_joint_3_trans">
    <type>transmission_interface/SimpleTransmission</type>
    <joint name="robot_j2s7s300_joint_3">
      <hardwareInterface>hardware_interface/EffortJointInterface</hardwareInterface>
    </joint>
    <actuator name="robot_j2s7s300_joint_3_actuator">
      <mechanicalReduction>160</mechanicalReduction>
    </actuator>
  </transmission>
  <link name="robot_j2s7s300_link_4">
    <visual>
      <geometry>
        <mesh filename="package://lunalab_summit_xl_gen_description/meshes/kinova/visual/forearm.dae"/>
      </geometry>
    </visual>
    <collision>
      <geometry>
        <mesh filename="package://lunalab_summit_xl_gen_description/meshes/kinova/collision/forearm.stl"/>
      </geometry>
    </collision>
    <inertial>
      <mass value="0.6763"/>
      <origin xyz="0 0.081 -0.0086"/>
      <inertia ixx="0.00142023" ixy="0" ixz="0" iyy="0.000304335" iyz="0" izz="0.00142023"/>
    </inertial>
  </link>
  <gazebo reference="robot_j2s7s300_link_4">
    <mu1 value="0.9"/>
    <mu2 value="0.9"/>
  </gazebo>
  <gazebo reference="robot_j2s7s300_link_4">
    <visual>
      <material>
        <diffuse>1 1 1 1</diffuse>
        <specular>1 1 1 1</specular>
        <pbr>
          <metal>
            <albedo_map>package://lunalab_summit_xl_gen_description/materials/textures/kinova/kinova_gen2_albedo.png</albedo_map>
            <roughness_map>package://lunalab_summit_xl_gen_description/materials/textures/kinova/kinova_gen2_roughness.png</roughness_map>
            <metalness_map>package://lunalab_summit_xl_gen_description/materials/textures/kinova/kinova_gen2_metalness.png</metalness_map>
          </metal>
        </pbr>
      </material>
    </visual>
  </gazebo>
  <joint name="robot_j2s7s300_joint_4" type="revolute">
    <parent link="robot_j2s7s300_link_3"/>
    <child link="robot_j2s7s300_link_4"/>
    <axis xyz="0 0 1"/>
    <limit effort="40" lower="0.5235987755982988" upper="5.759586531581287" velocity="0.6283185307179586"/>
    <origin rpy="1.5707963267948966 0 3.141592653589793" xyz="0 0 -0.205"/>
    <dynamics damping="8.0" friction="0.55"/>
    <safety_controller k_position="20" k_velocity="0.0" soft_lower_limit="0.6981317055982988" soft_upper_limit="5.585053601581287"/>
  </joint>
  <transmission name="robot_j2s7s300_joint_4_trans">
    <type>transmission_interface/SimpleTransmission</type>
    <joint name="robot_j2s7s300_joint_4">
      <hardwareInterface>hardware_interface/EffortJointInterface</hardwareInterface>
    </joint>
    <actuator name="robot_j2s7s300_joint_4_actuator">
      <mechanicalReduction>160</mechanicalReduction>
    </actuator>
  </transmission>
  <link name="robot_j2s7s300_link_5">
    <visual>
      <geometry>
        <mesh filename="package://lunalab_summit_xl_gen_description/meshes/kinova/visual/wrist_spherical_1.dae"/>
      </geometry>
    </visual>
    <collision>
      <geometry>
        <mesh filename="package://lunalab_summit_xl_gen_description/meshes/kinova/collision/wrist_spherical_1.stl"/>
      </geometry>
    </collision>
    <inertial>
      <mass value="0.463"/>
      <origin xyz="0 0.0028848942 -0.0541932613"/>
      <inertia ixx="0.00043213333333333345" ixy="0" ixz="0" iyy="0.00043213333333333345" iyz="0" izz="9.260000000000001e-05"/>
    </inertial>
  </link>
  <gazebo reference="robot_j2s7s300_link_5">
    <mu1 value="0.9"/>
    <mu2 value="0.9"/>
  </gazebo>
  <gazebo reference="robot_j2s7s300_link_5">
    <visual>
      <material>
        <diffuse>1 1 1 1</diffuse>
        <specular>1 1 1 1</specular>
        <pbr>
          <metal>
            <albedo_map>package://lunalab_summit_xl_gen_description/materials/textures/kinova/kinova_gen2_albedo.png</albedo_map>
            <roughness_map>package://lunalab_summit_xl_gen_description/materials/textures/kinova/kinova_gen2_roughness.png</roughness_map>
            <metalness_map>package://lunalab_summit_xl_gen_description/materials/textures/kinova/kinova_gen2_metalness.png</metalness_map>
          </metal>
        </pbr>
      </material>
    </visual>
  </gazebo>
  <joint name="robot_j2s7s300_joint_5" type="revolute">
    <parent link="robot_j2s7s300_link_4"/>
    <child link="robot_j2s7s300_link_5"/>
    <axis xyz="0 0 1"/>
    <limit effort="20" lower="-174.04423300887453" upper="174.04423300887453" velocity="0.8377580409572781"/>
    <origin rpy="-1.5707963267948966 0 3.141592653589793" xyz="0 0.2073 -0.0114"/>
    <dynamics damping="6.5" friction="0.35"/>
    <safety_controller k_position="20" k_velocity="0.0" soft_lower_limit="-173.86970007887453" soft_upper_limit="173.86970007887453"/>
  </joint>
  <transmission name="robot_j2s7s300_joint_5_trans">
    <type>transmission_interface/SimpleTransmission</type>
    <joint name="robot_j2s7s300_joint_5">
      <hardwareInterface>hardware_interface/EffortJointInterface</hardwareInterface>
    </joint>
    <actuator name="robot_j2s7s300_joint_5_actuator">
      <mechanicalReduction>160</mechanicalReduction>
    </actuator>
  </transmission>
  <link name="robot_j2s7s300_link_6">
    <visual>
      <geometry>
        <mesh filename="package://lunalab_summit_xl_gen_description/meshes/kinova/visual/wrist_spherical_2.dae"/>
      </geometry>
    </visual>
    <collision>
      <geometry>
        <mesh filename="package://lunalab_summit_xl_gen_description/meshes/kinova/collision/wrist_spherical_2.stl"/>
      </geometry>
    </collision>
    <inertial>
      <mass value="0.463"/>
      <origin xyz="0 0.0497208855 -0.0028562765"/>
      <inertia ixx="0.00043213333333333345" ixy="0" ixz="0" iyy="9.260000000000001e-05" iyz="0" izz="0.00043213333333333345"/>
    </inertial>
  </link>
  <gazebo reference="robot_j2s7s300_link_6">
    <mu1 value="0.9"/>
    <mu2 value="0.9"/>
  </gazebo>
  <gazebo reference="robot_j2s7s300_link_6">
    <visual>
      <material>
        <diffuse>1 1 1 1</diffuse>
        <specular>1 1 1 1</specular>
        <pbr>
          <metal>
            <albedo_map>package://lunalab_summit_xl_gen_description/materials/textures/kinova/kinova_gen2_albedo.png</albedo_map>
            <roughness_map>package://lunalab_summit_xl_gen_description/materials/textures/kinova/kinova_gen2_roughness.png</roughness_map>
            <metalness_map>package://lunalab_summit_xl_gen_description/materials/textures/kinova/kinova_gen2_metalness.png</metalness_map>
          </metal>
        </pbr>
      </material>
    </visual>
  </gazebo>
  <joint name="robot_j2s7s300_joint_6" type="revolute">
    <parent link="robot_j2s7s300_link_5"/>
    <child link="robot_j2s7s300_link_6"/>
    <axis xyz="0 0 1"/>
    <limit effort="20" lower="1.1344640137963142" upper="5.1487212933832724" velocity="0.8377580409572781"/>
    <origin rpy="1.5707963267948966 0 3.141592653589793" xyz="0 0 -0.10375"/>
    <dynamics damping="5.5" friction="0.25"/>
    <safety_controller k_position="20" k_velocity="0.0" soft_lower_limit="1.3089969437963143" soft_upper_limit="4.974188363383273"/>
  </joint>
  <transmission name="robot_j2s7s300_joint_6_trans">
    <type>transmission_interface/SimpleTransmission</type>
    <joint name="robot_j2s7s300_joint_6">
      <hardwareInterface>hardware_interface/EffortJointInterface</hardwareInterface>
    </joint>
    <actuator name="robot_j2s7s300_joint_6_actuator">
      <mechanicalReduction>160</mechanicalReduction>
    </actuator>
  </transmission>
  <link name="robot_j2s7s300_link_7">
    <visual>
      <geometry>
        <mesh filename="package://lunalab_summit_xl_gen_description/meshes/kinova/visual/hand_3finger.dae"/>
      </geometry>
    </visual>
    <collision>
      <geometry>
        <mesh filename="package://lunalab_summit_xl_gen_description/meshes/kinova/collision/hand_3finger.stl"/>
      </geometry>
    </collision>
    <inertial>
      <mass value="0.99"/>
      <origin xyz="0 0 -0.06"/>
      <inertia ixx="0.0003453249999999999" ixy="0" ixz="0" iyy="0.0003453249999999999" iyz="0" izz="0.0005815999999999999"/>
    </inertial>
  </link>
  <gazebo reference="robot_j2s7s300_link_7">
    <mu1 value="0.9"/>
    <mu2 value="0.9"/>
  </gazebo>
  <gazebo reference="robot_j2s7s300_link_7">
    <visual>
      <material>
        <diffuse>1 1 1 1</diffuse>
        <specular>1 1 1 1</specular>
        <pbr>
          <metal>
            <albedo_map>package://lunalab_summit_xl_gen_description/materials/textures/kinova/kinova_gen2_albedo.png</albedo_map>
            <roughness_map>package://lunalab_summit_xl_gen_description/materials/textures/kinova/kinova_gen2_roughness.png</roughness_map>
            <metalness_map>package://lunalab_summit_xl_gen_description/materials/textures/kinova/kinova_gen2_metalness.png</metalness_map>
          </metal>
        </pbr>
      </material>
    </visual>
  </gazebo>
  <joint name="robot_j2s7s300_joint_7" type="revolute">
    <parent link="robot_j2s7s300_link_6"/>
    <child link="robot_j2s7s300_link_7"/>
    <axis xyz="0 0 1"/>
    <limit effort="20" lower="-174.04423300887453" upper="174.04423300887453" velocity="0.8377580409572781"/>
    <origin rpy="-1.5707963267948966 0 3.141592653589793" xyz="0 0.10375 0"/>
    <dynamics damping="4.5" friction="0.2"/>
    <safety_controller k_position="20" k_velocity="0.0" soft_lower_limit="-173.86970007887453" soft_upper_limit="173.86970007887453"/>
  </joint>
  <transmission name="robot_j2s7s300_joint_7_trans">
    <type>transmission_interface/SimpleTransmission</type>
    <joint name="robot_j2s7s300_joint_7">
      <hardwareInterface>hardware_interface/EffortJointInterface</hardwareInterface>
    </joint>
    <actuator name="robot_j2s7s300_joint_7_actuator">
      <mechanicalReduction>160</mechanicalReduction>
    </actuator>
  </transmission>
  <link name="robot_j2s7s300_end_effector">
  </link>
  <joint name="robot_j2s7s300_joint_end_effector" type="fixed">
    <parent link="robot_j2s7s300_link_7"/>
    <child link="robot_j2s7s300_end_effector"/>
    <origin rpy="3.141592653589793 0 1.5707963267948966" xyz="0 0 -0.1600"/>
  </joint>
  <link name="robot_j2s7s300_link_finger_1">
    <visual>
      <geometry>
        <mesh filename="package://lunalab_summit_xl_gen_description/meshes/kinova/visual/finger_proximal.dae"/>
      </geometry>
    </visual>
    <collision>
      <geometry>
        <mesh filename="package://lunalab_summit_xl_gen_description/meshes/kinova/collision/finger_proximal.stl"/>
      </geometry>
    </collision>
    <inertial>
      <mass value="0.01"/>
      <origin xyz="0.022 0 0"/>
      <inertia ixx="7.9e-07" ixy="0" ixz="0" iyy="7.9e-07" iyz="0" izz="8e-08"/>
    </inertial>
  </link>
  <gazebo reference="robot_j2s7s300_link_finger_1">
    <mu1 value="1.6"/>
    <mu2 value="1.6"/>
  </gazebo>
  <gazebo reference="robot_j2s7s300_link_finger_1">
    <visual>
      <material>
        <diffuse>1 1 1 1</diffuse>
        <specular>1 1 1 1</specular>
        <pbr>
          <metal>
            <albedo_map>package://lunalab_summit_xl_gen_description/materials/textures/kinova/kinova_gen2_albedo.png</albedo_map>
            <roughness_map>package://lunalab_summit_xl_gen_description/materials/textures/kinova/kinova_gen2_roughness.png</roughness_map>
            <metalness_map>package://lunalab_summit_xl_gen_description/materials/textures/kinova/kinova_gen2_metalness.png</metalness_map>
          </metal>
        </pbr>
      </material>
    </visual>
  </gazebo>
  <joint name="robot_j2s7s300_joint_finger_1" type="revolute">
    <parent link="robot_j2s7s300_link_7"/>
    <child link="robot_j2s7s300_link_finger_1"/>
    <axis xyz="0 0 1"/>
    <origin rpy="-1.704955772138421 0.6492624817418906 1.6728980880365647" xyz="0.002786 0.03126 -0.114668"/>
    <limit effort="5.0" lower="0.0" upper="1.51" velocity="1.0"/>
    <dynamics damping="0.3" friction="0.01"/>
  </joint>
  <transmission name="robot_j2s7s300_joint_finger_1_trans">
    <type>transmission_interface/SimpleTransmission</type>
    <joint name="robot_j2s7s300_joint_finger_1">
      <hardwareInterface>hardware_interface/EffortJointInterface</hardwareInterface>
    </joint>
    <actuator name="robot_j2s7s300_joint_finger_1_actuator">
      <hardwareInterface>hardware_interface/EffortJointInterface</hardwareInterface>
      <mechanicalReduction>1</mechanicalReduction>
    </actuator>
  </transmission>
  <link name="robot_j2s7s300_link_finger_tip_1">
    <visual>
      <geometry>
        <mesh filename="package://lunalab_summit_xl_gen_description/meshes/kinova/visual/finger_distal.dae"/>
      </geometry>
    </visual>
    <collision>
      <geometry>
        <mesh filename="package://lunalab_summit_xl_gen_description/meshes/kinova/collision/finger_distal.stl"/>
      </geometry>
    </collision>
    <inertial>
      <mass value="0.01"/>
      <origin xyz="0.022 0 0"/>
      <inertia ixx="7.9e-07" ixy="0" ixz="0" iyy="7.9e-07" iyz="0" izz="8e-08"/>
    </inertial>
  </link>
  <gazebo reference="robot_j2s7s300_link_finger_tip_1">
    <mu1 value="1.6"/>
    <mu2 value="1.6"/>
  </gazebo>
  <gazebo reference="robot_j2s7s300_link_finger_tip_1">
    <visual>
      <material>
        <diffuse>1 1 1 1</diffuse>
        <specular>1 1 1 1</specular>
        <pbr>
          <metal>
            <albedo_map>package://lunalab_summit_xl_gen_description/materials/textures/kinova/kinova_gen2_albedo.png</albedo_map>
            <roughness_map>package://lunalab_summit_xl_gen_description/materials/textures/kinova/kinova_gen2_roughness.png</roughness_map>
            <metalness_map>package://lunalab_summit_xl_gen_description/materials/textures/kinova/kinova_gen2_metalness.png</metalness_map>
          </metal>
        </pbr>
      </material>
    </visual>
  </gazebo>
  <joint name="robot_j2s7s300_joint_finger_tip_1" type="revolute">
    <parent link="robot_j2s7s300_link_finger_1"/>
    <child link="robot_j2s7s300_link_finger_tip_1"/>
    <axis xyz="0 0 1"/>
    <origin rpy="0 0 0" xyz="0.044 -0.003 0"/>
    <limit effort="2.0" lower="0.0" upper="2.0" velocity="1.0"/>
    <dynamics damping="0.005" friction="0.00025"/>
  </joint>
  <transmission name="robot_j2s7s300_joint_finger_tip_1_trans">
    <type>transmission_interface/SimpleTransmission</type>
    <joint name="robot_j2s7s300_joint_finger_tip_1">
      <hardwareInterface>hardware_interface/EffortJointInterface</hardwareInterface>
    </joint>
    <actuator name="robot_j2s7s300_joint_finger_tip_1_actuator">
      <hardwareInterface>hardware_interface/EffortJointInterface</hardwareInterface>
      <mechanicalReduction>1</mechanicalReduction>
    </actuator>
  </transmission>
  <gazebo reference="robot_j2s7s300_joint_finger_tip_1">
    <springStiffness value="1.25"/>
    <springReference value="0.0"/>
  </gazebo>
  <gazebo reference="robot_j2s7s300_link_finger_tip_1">
    <self_collide>true</self_collide>
  </gazebo>
  <link name="robot_j2s7s300_link_finger_2">
    <visual>
      <geometry>
        <mesh filename="package://lunalab_summit_xl_gen_description/meshes/kinova/visual/finger_proximal.dae"/>
      </geometry>
    </visual>
    <collision>
      <geometry>
        <mesh filename="package://lunalab_summit_xl_gen_description/meshes/kinova/collision/finger_proximal.stl"/>
      </geometry>
    </collision>
    <inertial>
      <mass value="0.01"/>
      <origin xyz="0.022 0 0"/>
      <inertia ixx="7.9e-07" ixy="0" ixz="0" iyy="7.9e-07" iyz="0" izz="8e-08"/>
    </inertial>
  </link>
  <gazebo reference="robot_j2s7s300_link_finger_2">
    <mu1 value="1.6"/>
    <mu2 value="1.6"/>
  </gazebo>
  <gazebo reference="robot_j2s7s300_link_finger_2">
    <visual>
      <material>
        <diffuse>1 1 1 1</diffuse>
        <specular>1 1 1 1</specular>
        <pbr>
          <metal>
            <albedo_map>package://lunalab_summit_xl_gen_description/materials/textures/kinova/kinova_gen2_albedo.png</albedo_map>
            <roughness_map>package://lunalab_summit_xl_gen_description/materials/textures/kinova/kinova_gen2_roughness.png</roughness_map>
            <metalness_map>package://lunalab_summit_xl_gen_description/materials/textures/kinova/kinova_gen2_metalness.png</metalness_map>
          </metal>
        </pbr>
      </material>
    </visual>
  </gazebo>
  <joint name="robot_j2s7s300_joint_finger_2" type="revolute">
    <parent link="robot_j2s7s300_link_7"/>
    <child link="robot_j2s7s300_link_finger_2"/>
    <axis xyz="0 0 1"/>
    <origin rpy="-1.5707963267948966 0.6492624817418906 -1.3861404919338964" xyz="0.022256 -0.027073 -0.114668"/>
    <limit effort="5.0" lower="0.0" upper="1.51" velocity="1.0"/>
    <dynamics damping="0.3" friction="0.01"/>
  </joint>
  <transmission name="robot_j2s7s300_joint_finger_2_trans">
    <type>transmission_interface/SimpleTransmission</type>
    <joint name="robot_j2s7s300_joint_finger_2">
      <hardwareInterface>hardware_interface/EffortJointInterface</hardwareInterface>
    </joint>
    <actuator name="robot_j2s7s300_joint_finger_2_actuator">
      <hardwareInterface>hardware_interface/EffortJointInterface</hardwareInterface>
      <mechanicalReduction>1</mechanicalReduction>
    </actuator>
  </transmission>
  <link name="robot_j2s7s300_link_finger_tip_2">
    <visual>
      <geometry>
        <mesh filename="package://lunalab_summit_xl_gen_description/meshes/kinova/visual/finger_distal.dae"/>
      </geometry>
    </visual>
    <collision>
      <geometry>
        <mesh filename="package://lunalab_summit_xl_gen_description/meshes/kinova/collision/finger_distal.stl"/>
      </geometry>
    </collision>
    <inertial>
      <mass value="0.01"/>
      <origin xyz="0.022 0 0"/>
      <inertia ixx="7.9e-07" ixy="0" ixz="0" iyy="7.9e-07" iyz="0" izz="8e-08"/>
    </inertial>
  </link>
  <gazebo reference="robot_j2s7s300_link_finger_tip_2">
    <mu1 value="1.6"/>
    <mu2 value="1.6"/>
  </gazebo>
  <gazebo reference="robot_j2s7s300_link_finger_tip_2">
    <visual>
      <material>
        <diffuse>1 1 1 1</diffuse>
        <specular>1 1 1 1</specular>
        <pbr>
          <metal>
            <albedo_map>package://lunalab_summit_xl_gen_description/materials/textures/kinova/kinova_gen2_albedo.png</albedo_map>
            <roughness_map>package://lunalab_summit_xl_gen_description/materials/textures/kinova/kinova_gen2_roughness.png</roughness_map>
            <metalness_map>package://lunalab_summit_xl_gen_description/materials/textures/kinova/kinova_gen2_metalness.png</metalness_map>
          </metal>
        </pbr>
      </material>
    </visual>
  </gazebo>
  <joint name="robot_j2s7s300_joint_finger_tip_2" type="revolute">
    <parent link="robot_j2s7s300_link_finger_2"/>
    <child link="robot_j2s7s300_link_finger_tip_2"/>
    <axis xyz="0 0 1"/>
    <origin rpy="0 0 0" xyz="0.044 -0.003 0"/>
    <limit effort="2.0" lower="0.0" upper="2.0" velocity="1.0"/>
    <dynamics damping="0.005" friction="0.00025"/>
  </joint>
  <transmission name="robot_j2s7s300_joint_finger_tip_2_trans">
    <type>transmission_interface/SimpleTransmission</type>
    <joint name="robot_j2s7s300_joint_finger_tip_2">
      <hardwareInterface>hardware_interface/EffortJointInterface</hardwareInterface>
    </joint>
    <actuator name="robot_j2s7s300_joint_finger_tip_2_actuator">
      <hardwareInterface>hardware_interface/EffortJointInterface</hardwareInterface>
      <mechanicalReduction>1</mechanicalReduction>
    </actuator>
  </transmission>
  <gazebo reference="robot_j2s7s300_joint_finger_tip_2">
    <springStiffness value="1.25"/>
    <springReference value="0.0"/>
  </gazebo>
  <gazebo reference="robot_j2s7s300_link_finger_tip_2">
    <self_collide>true</self_collide>
  </gazebo>
  <link name="robot_j2s7s300_link_finger_3">
    <visual>
      <geometry>
        <mesh filename="package://lunalab_summit_xl_gen_description/meshes/kinova/visual/finger_proximal.dae"/>
      </geometry>
    </visual>
    <collision>
      <geometry>
        <mesh filename="package://lunalab_summit_xl_gen_description/meshes/kinova/collision/finger_proximal.stl"/>
      </geometry>
    </collision>
    <inertial>
      <mass value="0.01"/>
      <origin xyz="0.022 0 0"/>
      <inertia ixx="7.9e-07" ixy="0" ixz="0" iyy="7.9e-07" iyz="0" izz="8e-08"/>
    </inertial>
  </link>
  <gazebo reference="robot_j2s7s300_link_finger_3">
    <mu1 value="1.6"/>
    <mu2 value="1.6"/>
  </gazebo>
  <gazebo reference="robot_j2s7s300_link_finger_3">
    <visual>
      <material>
        <diffuse>1 1 1 1</diffuse>
        <specular>1 1 1 1</specular>
        <pbr>
          <metal>
            <albedo_map>package://lunalab_summit_xl_gen_description/materials/textures/kinova/kinova_gen2_albedo.png</albedo_map>
            <roughness_map>package://lunalab_summit_xl_gen_description/materials/textures/kinova/kinova_gen2_roughness.png</roughness_map>
            <metalness_map>package://lunalab_summit_xl_gen_description/materials/textures/kinova/kinova_gen2_metalness.png</metalness_map>
          </metal>
        </pbr>
      </material>
    </visual>
  </gazebo>
  <joint name="robot_j2s7s300_joint_finger_3" type="revolute">
    <parent link="robot_j2s7s300_link_7"/>
    <child link="robot_j2s7s300_link_finger_3"/>
    <axis xyz="0 0 1"/>
    <origin rpy="-1.5707963267948966 0.6492624817418906 -1.7554521616558967" xyz="-0.022256 -0.027073 -0.114668"/>
    <limit effort="5.0" lower="0.0" upper="1.51" velocity="1.0"/>
    <dynamics damping="0.3" friction="0.01"/>
  </joint>
  <transmission name="robot_j2s7s300_joint_finger_3_trans">
    <type>transmission_interface/SimpleTransmission</type>
    <joint name="robot_j2s7s300_joint_finger_3">
      <hardwareInterface>hardware_interface/EffortJointInterface</hardwareInterface>
    </joint>
    <actuator name="robot_j2s7s300_joint_finger_3_actuator">
      <hardwareInterface>hardware_interface/EffortJointInterface</hardwareInterface>
      <mechanicalReduction>1</mechanicalReduction>
    </actuator>
  </transmission>
  <link name="robot_j2s7s300_link_finger_tip_3">
    <visual>
      <geometry>
        <mesh filename="package://lunalab_summit_xl_gen_description/meshes/kinova/visual/finger_distal.dae"/>
      </geometry>
    </visual>
    <collision>
      <geometry>
        <mesh filename="package://lunalab_summit_xl_gen_description/meshes/kinova/collision/finger_distal.stl"/>
      </geometry>
    </collision>
    <inertial>
      <mass value="0.01"/>
      <origin xyz="0.022 0 0"/>
      <inertia ixx="7.9e-07" ixy="0" ixz="0" iyy="7.9e-07" iyz="0" izz="8e-08"/>
    </inertial>
  </link>
  <gazebo reference="robot_j2s7s300_link_finger_tip_3">
    <mu1 value="1.6"/>
    <mu2 value="1.6"/>
  </gazebo>
  <gazebo reference="robot_j2s7s300_link_finger_tip_3">
    <visual>
      <material>
        <diffuse>1 1 1 1</diffuse>
        <specular>1 1 1 1</specular>
        <pbr>
          <metal>
            <albedo_map>package://lunalab_summit_xl_gen_description/materials/textures/kinova/kinova_gen2_albedo.png</albedo_map>
            <roughness_map>package://lunalab_summit_xl_gen_description/materials/textures/kinova/kinova_gen2_roughness.png</roughness_map>
            <metalness_map>package://lunalab_summit_xl_gen_description/materials/textures/kinova/kinova_gen2_metalness.png</metalness_map>
          </metal>
        </pbr>
      </material>
    </visual>
  </gazebo>
  <joint name="robot_j2s7s300_joint_finger_tip_3" type="revolute">
    <parent link="robot_j2s7s300_link_finger_3"/>
    <child link="robot_j2s7s300_link_finger_tip_3"/>
    <axis xyz="0 0 1"/>
    <origin rpy="0 0 0" xyz="0.044 -0.003 0"/>
    <limit effort="2.0" lower="0.0" upper="2.0" velocity="1.0"/>
    <dynamics damping="0.005" friction="0.00025"/>
  </joint>
  <transmission name="robot_j2s7s300_joint_finger_tip_3_trans">
    <type>transmission_interface/SimpleTransmission</type>
    <joint name="robot_j2s7s300_joint_finger_tip_3">
      <hardwareInterface>hardware_interface/EffortJointInterface</hardwareInterface>
    </joint>
    <actuator name="robot_j2s7s300_joint_finger_tip_3_actuator">
      <hardwareInterface>hardware_interface/EffortJointInterface</hardwareInterface>
      <mechanicalReduction>1</mechanicalReduction>
    </actuator>
  </transmission>
  <gazebo reference="robot_j2s7s300_joint_finger_tip_3">
    <springStiffness value="1.25"/>
    <springReference value="0.0"/>
  </gazebo>
  <ros2_control name="KinovaArmSystem" type="system">
    <hardware>
      <plugin>ign_ros2_control/IgnitionSystem</plugin>
    </hardware>
    <joint name="robot_j2s7s300_joint_1">
      <param name="initial_position">0.0</param>
      <command_interface name="effort"/>
      <state_interface name="position"/>
      <state_interface name="velocity"/>
      <state_interface name="effort"/>
    </joint>
    <joint name="robot_j2s7s300_joint_2">
      <param name="initial_position">3.141592653589793</param>
      <command_interface name="effort"/>
      <state_interface name="position"/>
      <state_interface name="velocity"/>
      <state_interface name="effort"/>
    </joint>
    <joint name="robot_j2s7s300_joint_3">
      <param name="initial_position">0.0</param>
      <command_interface name="effort"/>
      <state_interface name="position"/>
      <state_interface name="velocity"/>
      <state_interface name="effort"/>
    </joint>
    <joint name="robot_j2s7s300_joint_4">
      <param name="initial_position">4.71238898038469</param>
      <command_interface name="effort"/>
      <state_interface name="position"/>
      <state_interface name="velocity"/>
      <state_interface name="effort"/>
    </joint>
    <joint name="robot_j2s7s300_joint_5">
      <param name="initial_position">0.0</param>
      <command_interface name="effort"/>
      <state_interface name="position"/>
      <state_interface name="velocity"/>
      <state_interface name="effort"/>
    </joint>
    <joint name="robot_j2s7s300_joint_6">
      <param name="initial_position">1.5707963267948966</param>
      <command_interface name="effort"/>
      <state_interface name="position"/>
      <state_interface name="velocity"/>
      <state_interface name="effort"/>
    </joint>
    <joint name="robot_j2s7s300_joint_7">
      <param name="initial_position">0.0</param>
      <command_interface name="effort"/>
      <state_interface name="position"/>
      <state_interface name="velocity"/>
      <state_interface name="effort"/>
    </joint>
  </ros2_control>
  <ros2_control name="KinovaGripperSystem" type="system">
    <hardware>
      <plugin>ign_ros2_control/IgnitionSystem</plugin>
    </hardware>
    <joint name="robot_j2s7s300_joint_finger_1">
      <param name="initial_position">0.2</param>
      <command_interface name="effort"/>
      <state_interface name="position"/>
      <state_interface name="velocity"/>
      <state_interface name="effort"/>
    </joint>
    <joint name="robot_j2s7s300_joint_finger_2">
      <param name="initial_position">0.2</param>
      <command_interface name="effort"/>
      <state_interface name="position"/>
      <state_interface name="velocity"/>
      <state_interface name="effort"/>
    </joint>
    <joint name="robot_j2s7s300_joint_finger_3">
      <param name="initial_position">0.2</param>
      <command_interface name="effort"/>
      <state_interface name="position"/>
      <state_interface name="velocity"/>
      <state_interface name="effort"/>
    </joint>
    <joint name="robot_j2s7s300_joint_finger_tip_1">
      <param name="initial_position">0</param>
      <state_interface name="position"/>
      <state_interface name="velocity"/>
      <state_interface name="effort"/>
    </joint>
    <joint name="robot_j2s7s300_joint_finger_tip_2">
      <param name="initial_position">0</param>
      <state_interface name="position"/>
      <state_interface name="velocity"/>
      <state_interface name="effort"/>
    </joint>
    <joint name="robot_j2s7s300_joint_finger_tip_3">
      <param name="initial_position">0</param>
      <state_interface name="position"/>
      <state_interface name="velocity"/>
      <state_interface name="effort"/>
    </joint>
  </ros2_control>
  <!-- Sensors -->
  <!-- <xacro:lunalab_summit_xl_sensors prefix="$(arg prefix)"/> -->
  <!-- Miscellaneous -->
  <!-- <xacro:lunalab_summit_xl_misc prefix="$(arg prefix)"/> -->
  <gazebo>
    <plugin filename="ign_ros2_control-system" name="ign_ros2_control::IgnitionROS2ControlPlugin">
      <parameters>/home/andrej/ws/code/repos/lunalab_summit_xl_gen/install/share/lunalab_summit_xl_gen_moveit_config/config/controllers_effort.yaml</parameters>
    </plugin>
  </gazebo>
  <gazebo>
    <plugin filename="ignition-gazebo-pose-publisher-system" name="ignition::gazebo::systems::PosePublisher">
      <use_pose_vector_msg>true</use_pose_vector_msg>
      <publish_nested_model_pose>true</publish_nested_model_pose>
      <publish_link_pose>false</publish_link_pose>
      <publish_collision_pose>false</publish_collision_pose>
      <publish_visual_pose>false</publish_visual_pose>
    </plugin>
  </gazebo>
</robot>
