<sdf version='1.9'>
  <model name='lunalab_summit_xl_gen'>
    <link name='robot_summit_xl_base_footprint'>
      <inertial>
        <pose>0.003747446190960834 0 0.1143260959704474 0 0 0</pose>
        <mass>25.467839999999999</mass>
        <inertia>
          <ixx>1.417421164692676</ixx>
          <ixy>0.0040000000000000001</ixy>
          <ixz>-0.022063089449281922</ixz>
          <iyy>6.8985331402665757</iyy>
          <iyz>0</iyz>
          <izz>6.1444862475738997</izz>
        </inertia>
      </inertial>
      <collision name='robot_summit_xl_base_footprint_fixed_joint_lump__robot_summit_xl_base_link_collision'>
        <pose>0 0 0.11 0 0 0</pose>
        <geometry>
          <mesh>
            <scale>1 1 1</scale>
            <uri>meshes/summit_xl/collision/summit_xl_chassis.stl</uri>
          </mesh>
        </geometry>
        <surface>
          <contact>
            <ode/>
          </contact>
          <friction>
            <ode/>
          </friction>
        </surface>
      </collision>
      <collision name='robot_summit_xl_base_footprint_fixed_joint_lump__robot_j2s7s300_link_base_collision_1'>
        <pose>0.204 0 0.22 0 0 0</pose>
        <geometry>
          <mesh>
            <scale>1 1 1</scale>
            <uri>meshes/kinova/collision/base.stl</uri>
          </mesh>
        </geometry>
        <surface>
          <contact>
            <ode/>
          </contact>
          <friction>
            <ode>
              <mu>0.90000000000000002</mu>
              <mu2>0.90000000000000002</mu2>
            </ode>
          </friction>
        </surface>
      </collision>
      <visual name='robot_summit_xl_base_footprint_fixed_joint_lump__robot_summit_xl_base_link_visual'>
        <pose>0 0 0.11 0 0 0</pose>
        <geometry>
          <mesh>
            <scale>1 1 1</scale>
            <uri>meshes/summit_xl/visual/summit_xl_chassis.dae</uri>
          </mesh>
        </geometry>
        <material>
          <diffuse>1 1 1 1</diffuse>
          <specular>1 1 1 1</specular>
          <pbr>
            <metal>
              <albedo_map>materials/textures/summit_xl/chassis_albedo.png</albedo_map>
              <roughness_map>materials/textures/summit_xl/chassis_roughness.png</roughness_map>
              <metalness_map>materials/textures/summit_xl/chassis_metalness.png</metalness_map>
            </metal>
          </pbr>
        </material>
      </visual>
      <visual name='robot_summit_xl_base_footprint_fixed_joint_lump__robot_j2s7s300_link_base_visual_1'>
        <pose>0.204 0 0.22 0 0 0</pose>
        <geometry>
          <mesh>
            <scale>1 1 1</scale>
            <uri>meshes/kinova/visual/base.dae</uri>
          </mesh>
        </geometry>
        <material>
          <diffuse>1 1 1 1</diffuse>
          <specular>1 1 1 1</specular>
          <pbr>
            <metal>
              <albedo_map>materials/textures/kinova/kinova_gen2_albedo.png</albedo_map>
              <roughness_map>materials/textures/kinova/kinova_gen2_roughness.png</roughness_map>
              <metalness_map>materials/textures/kinova/kinova_gen2_metalness.png</metalness_map>
            </metal>
          </pbr>
        </material>
      </visual>
    </link>
    <joint name='robot_j2s7s300_joint_1' type='revolute'>
      <pose relative_to='robot_summit_xl_base_footprint'>0.204 0 0.37675 3.141592653589793 1.224646799147353e-16 3.141592653589793</pose>
      <parent>robot_summit_xl_base_footprint</parent>
      <child>robot_j2s7s300_link_1</child>
      <axis>
        <xyz>0 0 1</xyz>
        <limit>
          <lower>-174.0442330088745</lower>
          <upper>174.0442330088745</upper>
          <effort>40</effort>
          <velocity>0.62831853071795862</velocity>
        </limit>
        <dynamics>
          <damping>15</damping>
          <friction>0.5</friction>
          <spring_reference>0</spring_reference>
          <spring_stiffness>0</spring_stiffness>
        </dynamics>
      </axis>
    </joint>
    <link name='robot_j2s7s300_link_1'>
      <pose relative_to='robot_j2s7s300_joint_1'>0 0 0 0 0 0</pose>
      <inertial>
        <pose>0 -0.002 -0.0605 0 0 0</pose>
        <mass>0.74770000000000003</mass>
        <inertia>
          <ixx>0.001520323333333333</ixx>
          <ixy>0</ixy>
          <ixz>0</ixz>
          <iyy>0.001520323333333333</iyy>
          <iyz>0</iyz>
          <izz>0.00059816000000000003</izz>
        </inertia>
      </inertial>
      <collision name='robot_j2s7s300_link_1_collision'>
        <pose>0 0 0 0 0 0</pose>
        <geometry>
          <mesh>
            <scale>1 1 1</scale>
            <uri>meshes/kinova/collision/shoulder.stl</uri>
          </mesh>
        </geometry>
        <surface>
          <contact>
            <ode/>
          </contact>
          <friction>
            <ode>
              <mu>0.90000000000000002</mu>
              <mu2>0.90000000000000002</mu2>
            </ode>
          </friction>
        </surface>
      </collision>
      <visual name='robot_j2s7s300_link_1_visual'>
        <pose>0 0 0 0 0 0</pose>
        <geometry>
          <mesh>
            <scale>1 1 1</scale>
            <uri>meshes/kinova/visual/shoulder.dae</uri>
          </mesh>
        </geometry>
        <material>
          <diffuse>1 1 1 1</diffuse>
          <specular>1 1 1 1</specular>
          <pbr>
            <metal>
              <albedo_map>materials/textures/kinova/kinova_gen2_albedo.png</albedo_map>
              <roughness_map>materials/textures/kinova/kinova_gen2_roughness.png</roughness_map>
              <metalness_map>materials/textures/kinova/kinova_gen2_metalness.png</metalness_map>
            </metal>
          </pbr>
        </material>
      </visual>
    </link>
    <joint name='robot_j2s7s300_joint_2' type='revolute'>
      <pose relative_to='robot_j2s7s300_link_1'>0 0.0016 -0.11875 -1.570796326794896 0 3.141592653589793</pose>
      <parent>robot_j2s7s300_link_1</parent>
      <child>robot_j2s7s300_link_2</child>
      <axis>
        <xyz>0 0 1</xyz>
        <limit>
          <lower>0.82030474843733492</lower>
          <upper>5.4628805587422509</upper>
          <effort>40</effort>
          <velocity>0.62831853071795862</velocity>
        </limit>
        <dynamics>
          <damping>16</damping>
          <friction>0.90000000000000002</friction>
          <spring_reference>0</spring_reference>
          <spring_stiffness>0</spring_stiffness>
        </dynamics>
      </axis>
    </joint>
    <link name='robot_j2s7s300_link_2'>
      <pose relative_to='robot_j2s7s300_joint_2'>0 0 0 0 0 0</pose>
      <inertial>
        <pose>0 -0.103563213 0 0 0 0</pose>
        <mass>0.84470000000000001</mass>
        <inertia>
          <ixx>0.0024707474999999999</ixx>
          <ixy>0</ixy>
          <ixz>0</ixz>
          <iyy>0.00038011499999999999</iyy>
          <iyz>0</iyz>
          <izz>0.0024707474999999999</izz>
        </inertia>
      </inertial>
      <collision name='robot_j2s7s300_link_2_collision'>
        <pose>0 0 0 0 0 0</pose>
        <geometry>
          <mesh>
            <scale>1 1 1</scale>
            <uri>meshes/kinova/collision/arm_half_1.stl</uri>
          </mesh>
        </geometry>
        <surface>
          <contact>
            <ode/>
          </contact>
          <friction>
            <ode>
              <mu>0.90000000000000002</mu>
              <mu2>0.90000000000000002</mu2>
            </ode>
          </friction>
        </surface>
      </collision>
      <visual name='robot_j2s7s300_link_2_visual'>
        <pose>0 0 0 0 0 0</pose>
        <geometry>
          <mesh>
            <scale>1 1 1</scale>
            <uri>meshes/kinova/visual/arm_half_1.dae</uri>
          </mesh>
        </geometry>
        <material>
          <diffuse>1 1 1 1</diffuse>
          <specular>1 1 1 1</specular>
          <pbr>
            <metal>
              <albedo_map>materials/textures/kinova/kinova_gen2_albedo.png</albedo_map>
              <roughness_map>materials/textures/kinova/kinova_gen2_roughness.png</roughness_map>
              <metalness_map>materials/textures/kinova/kinova_gen2_metalness.png</metalness_map>
            </metal>
          </pbr>
        </material>
      </visual>
    </link>
    <joint name='robot_j2s7s300_joint_3' type='revolute'>
      <pose relative_to='robot_j2s7s300_link_2'>0 -0.205 0 -1.570796326794896 0 0</pose>
      <parent>robot_j2s7s300_link_2</parent>
      <child>robot_j2s7s300_link_3</child>
      <axis>
        <xyz>0 0 1</xyz>
        <limit>
          <lower>-174.0442330088745</lower>
          <upper>174.0442330088745</upper>
          <effort>40</effort>
          <velocity>0.62831853071795862</velocity>
        </limit>
        <dynamics>
          <damping>12</damping>
          <friction>0.80000000000000004</friction>
          <spring_reference>0</spring_reference>
          <spring_stiffness>0</spring_stiffness>
        </dynamics>
      </axis>
    </joint>
    <link name='robot_j2s7s300_link_3'>
      <pose relative_to='robot_j2s7s300_joint_3'>0 0 0 0 0 0</pose>
      <inertial>
        <pose>0 0 -0.1022447445 0 0 0</pose>
        <mass>0.84470000000000001</mass>
        <inertia>
          <ixx>0.0024707474999999999</ixx>
          <ixy>0</ixy>
          <ixz>0</ixz>
          <iyy>0.0024707474999999999</iyy>
          <iyz>0</iyz>
          <izz>0.00038011499999999999</izz>
        </inertia>
      </inertial>
      <collision name='robot_j2s7s300_link_3_collision'>
        <pose>0 0 0 0 0 0</pose>
        <geometry>
          <mesh>
            <scale>1 1 1</scale>
            <uri>meshes/kinova/collision/arm_half_2.stl</uri>
          </mesh>
        </geometry>
        <surface>
          <contact>
            <ode/>
          </contact>
          <friction>
            <ode>
              <mu>0.90000000000000002</mu>
              <mu2>0.90000000000000002</mu2>
            </ode>
          </friction>
        </surface>
      </collision>
      <visual name='robot_j2s7s300_link_3_visual'>
        <pose>0 0 0 0 0 0</pose>
        <geometry>
          <mesh>
            <scale>1 1 1</scale>
            <uri>meshes/kinova/visual/arm_half_2.dae</uri>
          </mesh>
        </geometry>
        <material>
          <diffuse>1 1 1 1</diffuse>
          <specular>1 1 1 1</specular>
          <pbr>
            <metal>
              <albedo_map>materials/textures/kinova/kinova_gen2_albedo.png</albedo_map>
              <roughness_map>materials/textures/kinova/kinova_gen2_roughness.png</roughness_map>
              <metalness_map>materials/textures/kinova/kinova_gen2_metalness.png</metalness_map>
            </metal>
          </pbr>
        </material>
      </visual>
    </link>
    <joint name='robot_j2s7s300_joint_4' type='revolute'>
      <pose relative_to='robot_j2s7s300_link_3'>0 0 -0.205 1.570796326794896 0 3.141592653589793</pose>
      <parent>robot_j2s7s300_link_3</parent>
      <child>robot_j2s7s300_link_4</child>
      <axis>
        <xyz>0 0 1</xyz>
        <limit>
          <lower>0.52359877559829882</lower>
          <upper>5.7595865315812871</upper>
          <effort>40</effort>
          <velocity>0.62831853071795862</velocity>
        </limit>
        <dynamics>
          <damping>8</damping>
          <friction>0.55000000000000004</friction>
          <spring_reference>0</spring_reference>
          <spring_stiffness>0</spring_stiffness>
        </dynamics>
      </axis>
    </joint>
    <link name='robot_j2s7s300_link_4'>
      <pose relative_to='robot_j2s7s300_joint_4'>0 0 0 0 0 0</pose>
      <inertial>
        <pose>0 0.081 -0.0086 0 0 0</pose>
        <mass>0.67630000000000001</mass>
        <inertia>
          <ixx>0.00142023</ixx>
          <ixy>0</ixy>
          <ixz>0</ixz>
          <iyy>0.00030433499999999998</iyy>
          <iyz>0</iyz>
          <izz>0.00142023</izz>
        </inertia>
      </inertial>
      <collision name='robot_j2s7s300_link_4_collision'>
        <pose>0 0 0 0 0 0</pose>
        <geometry>
          <mesh>
            <scale>1 1 1</scale>
            <uri>meshes/kinova/collision/forearm.stl</uri>
          </mesh>
        </geometry>
        <surface>
          <contact>
            <ode/>
          </contact>
          <friction>
            <ode>
              <mu>0.90000000000000002</mu>
              <mu2>0.90000000000000002</mu2>
            </ode>
          </friction>
        </surface>
      </collision>
      <visual name='robot_j2s7s300_link_4_visual'>
        <pose>0 0 0 0 0 0</pose>
        <geometry>
          <mesh>
            <scale>1 1 1</scale>
            <uri>meshes/kinova/visual/forearm.dae</uri>
          </mesh>
        </geometry>
        <material>
          <diffuse>1 1 1 1</diffuse>
          <specular>1 1 1 1</specular>
          <pbr>
            <metal>
              <albedo_map>materials/textures/kinova/kinova_gen2_albedo.png</albedo_map>
              <roughness_map>materials/textures/kinova/kinova_gen2_roughness.png</roughness_map>
              <metalness_map>materials/textures/kinova/kinova_gen2_metalness.png</metalness_map>
            </metal>
          </pbr>
        </material>
      </visual>
    </link>
    <joint name='robot_j2s7s300_joint_5' type='revolute'>
      <pose relative_to='robot_j2s7s300_link_4'>0 0.2073 -0.0114 -1.570796326794896 0 3.141592653589793</pose>
      <parent>robot_j2s7s300_link_4</parent>
      <child>robot_j2s7s300_link_5</child>
      <axis>
        <xyz>0 0 1</xyz>
        <limit>
          <lower>-174.0442330088745</lower>
          <upper>174.0442330088745</upper>
          <effort>20</effort>
          <velocity>0.83775804095727813</velocity>
        </limit>
        <dynamics>
          <damping>6.5</damping>
          <friction>0.34999999999999998</friction>
          <spring_reference>0</spring_reference>
          <spring_stiffness>0</spring_stiffness>
        </dynamics>
      </axis>
    </joint>
    <link name='robot_j2s7s300_link_5'>
      <pose relative_to='robot_j2s7s300_joint_5'>0 0 0 0 0 0</pose>
      <inertial>
        <pose>0 0.0028848942 -0.0541932613 0 0 0</pose>
        <mass>0.46300000000000002</mass>
        <inertia>
          <ixx>0.00043213333333333339</ixx>
          <ixy>0</ixy>
          <ixz>0</ixz>
          <iyy>0.00043213333333333339</iyy>
          <iyz>0</iyz>
          <izz>9.2600000000000015e-05</izz>
        </inertia>
      </inertial>
      <collision name='robot_j2s7s300_link_5_collision'>
        <pose>0 0 0 0 0 0</pose>
        <geometry>
          <mesh>
            <scale>1 1 1</scale>
            <uri>meshes/kinova/collision/wrist_spherical_1.stl</uri>
          </mesh>
        </geometry>
        <surface>
          <contact>
            <ode/>
          </contact>
          <friction>
            <ode>
              <mu>0.90000000000000002</mu>
              <mu2>0.90000000000000002</mu2>
            </ode>
          </friction>
        </surface>
      </collision>
      <visual name='robot_j2s7s300_link_5_visual'>
        <pose>0 0 0 0 0 0</pose>
        <geometry>
          <mesh>
            <scale>1 1 1</scale>
            <uri>meshes/kinova/visual/wrist_spherical_1.dae</uri>
          </mesh>
        </geometry>
        <material>
          <diffuse>1 1 1 1</diffuse>
          <specular>1 1 1 1</specular>
          <pbr>
            <metal>
              <albedo_map>materials/textures/kinova/kinova_gen2_albedo.png</albedo_map>
              <roughness_map>materials/textures/kinova/kinova_gen2_roughness.png</roughness_map>
              <metalness_map>materials/textures/kinova/kinova_gen2_metalness.png</metalness_map>
            </metal>
          </pbr>
        </material>
      </visual>
    </link>
    <joint name='robot_j2s7s300_joint_6' type='revolute'>
      <pose relative_to='robot_j2s7s300_link_5'>0 0 -0.10375 1.570796326794896 0 3.141592653589793</pose>
      <parent>robot_j2s7s300_link_5</parent>
      <child>robot_j2s7s300_link_6</child>
      <axis>
        <xyz>0 0 1</xyz>
        <limit>
          <lower>1.134464013796314</lower>
          <upper>5.1487212933832716</upper>
          <effort>20</effort>
          <velocity>0.83775804095727813</velocity>
        </limit>
        <dynamics>
          <damping>5.5</damping>
          <friction>0.25</friction>
          <spring_reference>0</spring_reference>
          <spring_stiffness>0</spring_stiffness>
        </dynamics>
      </axis>
    </joint>
    <link name='robot_j2s7s300_link_6'>
      <pose relative_to='robot_j2s7s300_joint_6'>0 0 0 0 0 0</pose>
      <inertial>
        <pose>0 0.0497208855 -0.0028562765 0 0 0</pose>
        <mass>0.46300000000000002</mass>
        <inertia>
          <ixx>0.00043213333333333339</ixx>
          <ixy>0</ixy>
          <ixz>0</ixz>
          <iyy>9.2600000000000015e-05</iyy>
          <iyz>0</iyz>
          <izz>0.00043213333333333339</izz>
        </inertia>
      </inertial>
      <collision name='robot_j2s7s300_link_6_collision'>
        <pose>0 0 0 0 0 0</pose>
        <geometry>
          <mesh>
            <scale>1 1 1</scale>
            <uri>meshes/kinova/collision/wrist_spherical_2.stl</uri>
          </mesh>
        </geometry>
        <surface>
          <contact>
            <ode/>
          </contact>
          <friction>
            <ode>
              <mu>0.90000000000000002</mu>
              <mu2>0.90000000000000002</mu2>
            </ode>
          </friction>
        </surface>
      </collision>
      <visual name='robot_j2s7s300_link_6_visual'>
        <pose>0 0 0 0 0 0</pose>
        <geometry>
          <mesh>
            <scale>1 1 1</scale>
            <uri>meshes/kinova/visual/wrist_spherical_2.dae</uri>
          </mesh>
        </geometry>
        <material>
          <diffuse>1 1 1 1</diffuse>
          <specular>1 1 1 1</specular>
          <pbr>
            <metal>
              <albedo_map>materials/textures/kinova/kinova_gen2_albedo.png</albedo_map>
              <roughness_map>materials/textures/kinova/kinova_gen2_roughness.png</roughness_map>
              <metalness_map>materials/textures/kinova/kinova_gen2_metalness.png</metalness_map>
            </metal>
          </pbr>
        </material>
      </visual>
    </link>
    <joint name='robot_j2s7s300_joint_7' type='revolute'>
      <pose relative_to='robot_j2s7s300_link_6'>0 0.10375 0 -1.570796326794896 0 3.141592653589793</pose>
      <parent>robot_j2s7s300_link_6</parent>
      <child>robot_j2s7s300_link_7</child>
      <axis>
        <xyz>0 0 1</xyz>
        <limit>
          <lower>-174.0442330088745</lower>
          <upper>174.0442330088745</upper>
          <effort>20</effort>
          <velocity>0.83775804095727813</velocity>
        </limit>
        <dynamics>
          <damping>4.5</damping>
          <friction>0.20000000000000001</friction>
          <spring_reference>0</spring_reference>
          <spring_stiffness>0</spring_stiffness>
        </dynamics>
      </axis>
    </joint>
    <link name='robot_j2s7s300_link_7'>
      <pose relative_to='robot_j2s7s300_joint_7'>0 0 0 0 0 0</pose>
      <inertial>
        <pose>0 0 -0.06 0 0 0</pose>
        <mass>0.98999999999999999</mass>
        <inertia>
          <ixx>0.0003453249999999999</ixx>
          <ixy>0</ixy>
          <ixz>0</ixz>
          <iyy>0.0003453249999999999</iyy>
          <iyz>0</iyz>
          <izz>0.00058159999999999993</izz>
        </inertia>
      </inertial>
      <collision name='robot_j2s7s300_link_7_collision'>
        <pose>0 0 0 0 0 0</pose>
        <geometry>
          <mesh>
            <scale>1 1 1</scale>
            <uri>meshes/kinova/collision/hand_3finger.stl</uri>
          </mesh>
        </geometry>
        <surface>
          <contact>
            <ode/>
          </contact>
          <friction>
            <ode>
              <mu>0.90000000000000002</mu>
              <mu2>0.90000000000000002</mu2>
            </ode>
          </friction>
        </surface>
      </collision>
      <visual name='robot_j2s7s300_link_7_visual'>
        <pose>0 0 0 0 0 0</pose>
        <geometry>
          <mesh>
            <scale>1 1 1</scale>
            <uri>meshes/kinova/visual/hand_3finger.dae</uri>
          </mesh>
        </geometry>
        <material>
          <diffuse>1 1 1 1</diffuse>
          <specular>1 1 1 1</specular>
          <pbr>
            <metal>
              <albedo_map>materials/textures/kinova/kinova_gen2_albedo.png</albedo_map>
              <roughness_map>materials/textures/kinova/kinova_gen2_roughness.png</roughness_map>
              <metalness_map>materials/textures/kinova/kinova_gen2_metalness.png</metalness_map>
            </metal>
          </pbr>
        </material>
      </visual>
    </link>
    <joint name='robot_j2s7s300_joint_finger_1' type='revolute'>
      <pose relative_to='robot_j2s7s300_link_7'>0.002786 0.03126 -0.114668 -1.704955772138421 0.6492624817418906 1.672898088036564</pose>
      <parent>robot_j2s7s300_link_7</parent>
      <child>robot_j2s7s300_link_finger_1</child>
      <axis>
        <xyz>0 0 1</xyz>
        <limit>
          <lower>0</lower>
          <upper>1.51</upper>
          <effort>5</effort>
          <velocity>1</velocity>
        </limit>
        <dynamics>
          <damping>0.29999999999999999</damping>
          <friction>0.01</friction>
          <spring_reference>0</spring_reference>
          <spring_stiffness>0</spring_stiffness>
        </dynamics>
      </axis>
    </joint>
    <link name='robot_j2s7s300_link_finger_1'>
      <pose relative_to='robot_j2s7s300_joint_finger_1'>0 0 0 0 0 0</pose>
      <inertial>
        <pose>0.022 0 0 0 0 0</pose>
        <mass>0.01</mass>
        <inertia>
          <ixx>7.8999999999999995e-07</ixx>
          <ixy>0</ixy>
          <ixz>0</ixz>
          <iyy>7.8999999999999995e-07</iyy>
          <iyz>0</iyz>
          <izz>8.0000000000000002e-08</izz>
        </inertia>
      </inertial>
      <collision name='robot_j2s7s300_link_finger_1_collision'>
        <pose>0 0 0 0 0 0</pose>
        <geometry>
          <mesh>
            <scale>1 1 1</scale>
            <uri>meshes/kinova/collision/finger_proximal.stl</uri>
          </mesh>
        </geometry>
        <surface>
          <contact>
            <ode/>
          </contact>
          <friction>
            <ode>
              <mu>1.6000000000000001</mu>
              <mu2>1.6000000000000001</mu2>
            </ode>
          </friction>
        </surface>
      </collision>
      <visual name='robot_j2s7s300_link_finger_1_visual'>
        <pose>0 0 0 0 0 0</pose>
        <geometry>
          <mesh>
            <scale>1 1 1</scale>
            <uri>meshes/kinova/visual/finger_proximal.dae</uri>
          </mesh>
        </geometry>
        <material>
          <diffuse>1 1 1 1</diffuse>
          <specular>1 1 1 1</specular>
          <pbr>
            <metal>
              <albedo_map>materials/textures/kinova/kinova_gen2_albedo.png</albedo_map>
              <roughness_map>materials/textures/kinova/kinova_gen2_roughness.png</roughness_map>
              <metalness_map>materials/textures/kinova/kinova_gen2_metalness.png</metalness_map>
            </metal>
          </pbr>
        </material>
      </visual>
    </link>
    <joint name='robot_j2s7s300_joint_finger_tip_1' type='revolute'>
      <pose relative_to='robot_j2s7s300_link_finger_1'>0.044 -0.003 0 0 0 0</pose>
      <parent>robot_j2s7s300_link_finger_1</parent>
      <child>robot_j2s7s300_link_finger_tip_1</child>
      <axis>
        <xyz>0 0 1</xyz>
        <limit>
          <lower>0</lower>
          <upper>2</upper>
          <effort>2</effort>
          <velocity>1</velocity>
        </limit>
        <dynamics>
          <damping>0.0050000000000000001</damping>
          <friction>0.00025000000000000001</friction>
          <spring_reference>0</spring_reference>
          <spring_stiffness>1.25</spring_stiffness>
        </dynamics>
      </axis>
      <physics>
        <ode>
          <limit>
            <cfm>0</cfm>
            <erp>0.20000000000000001</erp>
          </limit>
        </ode>
      </physics>
    </joint>
    <link name='robot_j2s7s300_link_finger_tip_1'>
      <pose relative_to='robot_j2s7s300_joint_finger_tip_1'>0 0 0 0 0 0</pose>
      <inertial>
        <pose>0.022 0 0 0 0 0</pose>
        <mass>0.01</mass>
        <inertia>
          <ixx>7.8999999999999995e-07</ixx>
          <ixy>0</ixy>
          <ixz>0</ixz>
          <iyy>7.8999999999999995e-07</iyy>
          <iyz>0</iyz>
          <izz>8.0000000000000002e-08</izz>
        </inertia>
      </inertial>
      <collision name='robot_j2s7s300_link_finger_tip_1_collision'>
        <pose>0 0 0 0 0 0</pose>
        <geometry>
          <mesh>
            <scale>1 1 1</scale>
            <uri>meshes/kinova/collision/finger_distal.stl</uri>
          </mesh>
        </geometry>
        <surface>
          <contact>
            <ode/>
          </contact>
          <friction>
            <ode>
              <mu>1.6000000000000001</mu>
              <mu2>1.6000000000000001</mu2>
            </ode>
          </friction>
        </surface>
      </collision>
      <visual name='robot_j2s7s300_link_finger_tip_1_visual'>
        <pose>0 0 0 0 0 0</pose>
        <geometry>
          <mesh>
            <scale>1 1 1</scale>
            <uri>meshes/kinova/visual/finger_distal.dae</uri>
          </mesh>
        </geometry>
        <material>
          <diffuse>1 1 1 1</diffuse>
          <specular>1 1 1 1</specular>
          <pbr>
            <metal>
              <albedo_map>materials/textures/kinova/kinova_gen2_albedo.png</albedo_map>
              <roughness_map>materials/textures/kinova/kinova_gen2_roughness.png</roughness_map>
              <metalness_map>materials/textures/kinova/kinova_gen2_metalness.png</metalness_map>
            </metal>
          </pbr>
        </material>
      </visual>
      <self_collide>true</self_collide>
    </link>
    <joint name='robot_j2s7s300_joint_finger_2' type='revolute'>
      <pose relative_to='robot_j2s7s300_link_7'>0.022256 -0.027073 -0.114668 -1.570796326794897 0.6492624817418907 -1.386140491933897</pose>
      <parent>robot_j2s7s300_link_7</parent>
      <child>robot_j2s7s300_link_finger_2</child>
      <axis>
        <xyz>0 0 1</xyz>
        <limit>
          <lower>0</lower>
          <upper>1.51</upper>
          <effort>5</effort>
          <velocity>1</velocity>
        </limit>
        <dynamics>
          <damping>0.29999999999999999</damping>
          <friction>0.01</friction>
          <spring_reference>0</spring_reference>
          <spring_stiffness>0</spring_stiffness>
        </dynamics>
      </axis>
    </joint>
    <link name='robot_j2s7s300_link_finger_2'>
      <pose relative_to='robot_j2s7s300_joint_finger_2'>0 0 0 0 0 0</pose>
      <inertial>
        <pose>0.022 0 0 0 0 0</pose>
        <mass>0.01</mass>
        <inertia>
          <ixx>7.8999999999999995e-07</ixx>
          <ixy>0</ixy>
          <ixz>0</ixz>
          <iyy>7.8999999999999995e-07</iyy>
          <iyz>0</iyz>
          <izz>8.0000000000000002e-08</izz>
        </inertia>
      </inertial>
      <collision name='robot_j2s7s300_link_finger_2_collision'>
        <pose>0 0 0 0 0 0</pose>
        <geometry>
          <mesh>
            <scale>1 1 1</scale>
            <uri>meshes/kinova/collision/finger_proximal.stl</uri>
          </mesh>
        </geometry>
        <surface>
          <contact>
            <ode/>
          </contact>
          <friction>
            <ode>
              <mu>1.6000000000000001</mu>
              <mu2>1.6000000000000001</mu2>
            </ode>
          </friction>
        </surface>
      </collision>
      <visual name='robot_j2s7s300_link_finger_2_visual'>
        <pose>0 0 0 0 0 0</pose>
        <geometry>
          <mesh>
            <scale>1 1 1</scale>
            <uri>meshes/kinova/visual/finger_proximal.dae</uri>
          </mesh>
        </geometry>
        <material>
          <diffuse>1 1 1 1</diffuse>
          <specular>1 1 1 1</specular>
          <pbr>
            <metal>
              <albedo_map>materials/textures/kinova/kinova_gen2_albedo.png</albedo_map>
              <roughness_map>materials/textures/kinova/kinova_gen2_roughness.png</roughness_map>
              <metalness_map>materials/textures/kinova/kinova_gen2_metalness.png</metalness_map>
            </metal>
          </pbr>
        </material>
      </visual>
    </link>
    <joint name='robot_j2s7s300_joint_finger_tip_2' type='revolute'>
      <pose relative_to='robot_j2s7s300_link_finger_2'>0.044 -0.003 0 0 0 0</pose>
      <parent>robot_j2s7s300_link_finger_2</parent>
      <child>robot_j2s7s300_link_finger_tip_2</child>
      <axis>
        <xyz>0 0 1</xyz>
        <limit>
          <lower>0</lower>
          <upper>2</upper>
          <effort>2</effort>
          <velocity>1</velocity>
        </limit>
        <dynamics>
          <damping>0.0050000000000000001</damping>
          <friction>0.00025000000000000001</friction>
          <spring_reference>0</spring_reference>
          <spring_stiffness>1.25</spring_stiffness>
        </dynamics>
      </axis>
      <physics>
        <ode>
          <limit>
            <cfm>0</cfm>
            <erp>0.20000000000000001</erp>
          </limit>
        </ode>
      </physics>
    </joint>
    <link name='robot_j2s7s300_link_finger_tip_2'>
      <pose relative_to='robot_j2s7s300_joint_finger_tip_2'>0 0 0 0 0 0</pose>
      <inertial>
        <pose>0.022 0 0 0 0 0</pose>
        <mass>0.01</mass>
        <inertia>
          <ixx>7.8999999999999995e-07</ixx>
          <ixy>0</ixy>
          <ixz>0</ixz>
          <iyy>7.8999999999999995e-07</iyy>
          <iyz>0</iyz>
          <izz>8.0000000000000002e-08</izz>
        </inertia>
      </inertial>
      <collision name='robot_j2s7s300_link_finger_tip_2_collision'>
        <pose>0 0 0 0 0 0</pose>
        <geometry>
          <mesh>
            <scale>1 1 1</scale>
            <uri>meshes/kinova/collision/finger_distal.stl</uri>
          </mesh>
        </geometry>
        <surface>
          <contact>
            <ode/>
          </contact>
          <friction>
            <ode>
              <mu>1.6000000000000001</mu>
              <mu2>1.6000000000000001</mu2>
            </ode>
          </friction>
        </surface>
      </collision>
      <visual name='robot_j2s7s300_link_finger_tip_2_visual'>
        <pose>0 0 0 0 0 0</pose>
        <geometry>
          <mesh>
            <scale>1 1 1</scale>
            <uri>meshes/kinova/visual/finger_distal.dae</uri>
          </mesh>
        </geometry>
        <material>
          <diffuse>1 1 1 1</diffuse>
          <specular>1 1 1 1</specular>
          <pbr>
            <metal>
              <albedo_map>materials/textures/kinova/kinova_gen2_albedo.png</albedo_map>
              <roughness_map>materials/textures/kinova/kinova_gen2_roughness.png</roughness_map>
              <metalness_map>materials/textures/kinova/kinova_gen2_metalness.png</metalness_map>
            </metal>
          </pbr>
        </material>
      </visual>
      <self_collide>true</self_collide>
    </link>
    <joint name='robot_j2s7s300_joint_finger_3' type='revolute'>
      <pose relative_to='robot_j2s7s300_link_7'>-0.022256 -0.027073 -0.114668 -1.570796326794896 0.6492624817418907 -1.755452161655896</pose>
      <parent>robot_j2s7s300_link_7</parent>
      <child>robot_j2s7s300_link_finger_3</child>
      <axis>
        <xyz>0 0 1</xyz>
        <limit>
          <lower>0</lower>
          <upper>1.51</upper>
          <effort>5</effort>
          <velocity>1</velocity>
        </limit>
        <dynamics>
          <damping>0.29999999999999999</damping>
          <friction>0.01</friction>
          <spring_reference>0</spring_reference>
          <spring_stiffness>0</spring_stiffness>
        </dynamics>
      </axis>
    </joint>
    <link name='robot_j2s7s300_link_finger_3'>
      <pose relative_to='robot_j2s7s300_joint_finger_3'>0 0 0 0 0 0</pose>
      <inertial>
        <pose>0.022 0 0 0 0 0</pose>
        <mass>0.01</mass>
        <inertia>
          <ixx>7.8999999999999995e-07</ixx>
          <ixy>0</ixy>
          <ixz>0</ixz>
          <iyy>7.8999999999999995e-07</iyy>
          <iyz>0</iyz>
          <izz>8.0000000000000002e-08</izz>
        </inertia>
      </inertial>
      <collision name='robot_j2s7s300_link_finger_3_collision'>
        <pose>0 0 0 0 0 0</pose>
        <geometry>
          <mesh>
            <scale>1 1 1</scale>
            <uri>meshes/kinova/collision/finger_proximal.stl</uri>
          </mesh>
        </geometry>
        <surface>
          <contact>
            <ode/>
          </contact>
          <friction>
            <ode>
              <mu>1.6000000000000001</mu>
              <mu2>1.6000000000000001</mu2>
            </ode>
          </friction>
        </surface>
      </collision>
      <visual name='robot_j2s7s300_link_finger_3_visual'>
        <pose>0 0 0 0 0 0</pose>
        <geometry>
          <mesh>
            <scale>1 1 1</scale>
            <uri>meshes/kinova/visual/finger_proximal.dae</uri>
          </mesh>
        </geometry>
        <material>
          <diffuse>1 1 1 1</diffuse>
          <specular>1 1 1 1</specular>
          <pbr>
            <metal>
              <albedo_map>materials/textures/kinova/kinova_gen2_albedo.png</albedo_map>
              <roughness_map>materials/textures/kinova/kinova_gen2_roughness.png</roughness_map>
              <metalness_map>materials/textures/kinova/kinova_gen2_metalness.png</metalness_map>
            </metal>
          </pbr>
        </material>
      </visual>
    </link>
    <joint name='robot_j2s7s300_joint_finger_tip_3' type='revolute'>
      <pose relative_to='robot_j2s7s300_link_finger_3'>0.044 -0.003 0 0 0 0</pose>
      <parent>robot_j2s7s300_link_finger_3</parent>
      <child>robot_j2s7s300_link_finger_tip_3</child>
      <axis>
        <xyz>0 0 1</xyz>
        <limit>
          <lower>0</lower>
          <upper>2</upper>
          <effort>2</effort>
          <velocity>1</velocity>
        </limit>
        <dynamics>
          <damping>0.0050000000000000001</damping>
          <friction>0.00025000000000000001</friction>
          <spring_reference>0</spring_reference>
          <spring_stiffness>1.25</spring_stiffness>
        </dynamics>
      </axis>
      <physics>
        <ode>
          <limit>
            <cfm>0</cfm>
            <erp>0.20000000000000001</erp>
          </limit>
        </ode>
      </physics>
    </joint>
    <link name='robot_j2s7s300_link_finger_tip_3'>
      <pose relative_to='robot_j2s7s300_joint_finger_tip_3'>0 0 0 0 0 0</pose>
      <inertial>
        <pose>0.022 0 0 0 0 0</pose>
        <mass>0.01</mass>
        <inertia>
          <ixx>7.8999999999999995e-07</ixx>
          <ixy>0</ixy>
          <ixz>0</ixz>
          <iyy>7.8999999999999995e-07</iyy>
          <iyz>0</iyz>
          <izz>8.0000000000000002e-08</izz>
        </inertia>
      </inertial>
      <collision name='robot_j2s7s300_link_finger_tip_3_collision'>
        <pose>0 0 0 0 0 0</pose>
        <geometry>
          <mesh>
            <scale>1 1 1</scale>
            <uri>meshes/kinova/collision/finger_distal.stl</uri>
          </mesh>
        </geometry>
        <surface>
          <contact>
            <ode/>
          </contact>
          <friction>
            <ode>
              <mu>1.6000000000000001</mu>
              <mu2>1.6000000000000001</mu2>
            </ode>
          </friction>
        </surface>
      </collision>
      <visual name='robot_j2s7s300_link_finger_tip_3_visual'>
        <pose>0 0 0 0 0 0</pose>
        <geometry>
          <mesh>
            <scale>1 1 1</scale>
            <uri>meshes/kinova/visual/finger_distal.dae</uri>
          </mesh>
        </geometry>
        <material>
          <diffuse>1 1 1 1</diffuse>
          <specular>1 1 1 1</specular>
          <pbr>
            <metal>
              <albedo_map>materials/textures/kinova/kinova_gen2_albedo.png</albedo_map>
              <roughness_map>materials/textures/kinova/kinova_gen2_roughness.png</roughness_map>
              <metalness_map>materials/textures/kinova/kinova_gen2_metalness.png</metalness_map>
            </metal>
          </pbr>
        </material>
      </visual>
    </link>
    <joint name='robot_summit_xl_back_left_wheel_joint' type='revolute'>
      <pose relative_to='robot_summit_xl_base_footprint'>-0.229 0.235 0.11 0 0 0</pose>
      <parent>robot_summit_xl_base_footprint</parent>
      <child>robot_summit_xl_back_left_wheel</child>
      <axis>
        <xyz>0 1 0</xyz>
        <limit>
          <effort>100</effort>
          <velocity>100</velocity>
          <lower>-10000000000000000</lower>
          <upper>10000000000000000</upper>
        </limit>
        <dynamics>
          <damping>0.035000000000000003</damping>
          <friction>0.00050000000000000001</friction>
          <spring_reference>0</spring_reference>
          <spring_stiffness>0</spring_stiffness>
        </dynamics>
      </axis>
    </joint>
    <link name='robot_summit_xl_back_left_wheel'>
      <pose relative_to='robot_summit_xl_back_left_wheel_joint'>0 0 0 0 0 0</pose>
      <inertial>
        <pose>0 0 0 0 0 0</pose>
        <mass>6.5</mass>
        <inertia>
          <ixx>0.031850000000000003</ixx>
          <ixy>0</ixy>
          <ixz>0</ixz>
          <iyy>0.039324999999999999</iyy>
          <iyz>0</iyz>
          <izz>0.031850000000000003</izz>
        </inertia>
      </inertial>
      <collision name='robot_summit_xl_back_left_wheel_collision'>
        <pose>0 0 0 1.570796326794896 0 0</pose>
        <geometry>
          <cylinder>
            <length>0.14999999999999999</length>
            <radius>0.11</radius>
          </cylinder>
        </geometry>
        <surface>
          <contact>
            <ode/>
          </contact>
          <friction>
            <ode>
              <mu>1.8999999999999999</mu>
              <mu2>1.7</mu2>
              <fdir1>1 0 0</fdir1>
            </ode>
          </friction>
        </surface>
      </collision>
      <visual name='robot_summit_xl_back_left_wheel_visual'>
        <pose>0 0 0 0 0 0</pose>
        <geometry>
          <mesh>
            <scale>1 1 1</scale>
            <uri>meshes/summit_xl/visual/rubber_wheel_left.dae</uri>
          </mesh>
        </geometry>
        <material>
          <diffuse>1 1 1 1</diffuse>
          <specular>1 1 1 1</specular>
          <pbr>
            <metal>
              <albedo_map>materials/textures/summit_xl/rubber_wheel_albedo.png</albedo_map>
              <normal_map>materials/textures/summit_xl/rubber_wheel_normal.png</normal_map>
              <roughness_map>materials/textures/summit_xl/rubber_wheel_roughness.png</roughness_map>
              <metalness_map>materials/textures/summit_xl/rubber_wheel_metalness.png</metalness_map>
            </metal>
          </pbr>
        </material>
      </visual>
    </link>
    <joint name='robot_summit_xl_back_right_wheel_joint' type='revolute'>
      <pose relative_to='robot_summit_xl_base_footprint'>-0.229 -0.235 0.11 0 0 0</pose>
      <parent>robot_summit_xl_base_footprint</parent>
      <child>robot_summit_xl_back_right_wheel</child>
      <axis>
        <xyz>0 1 0</xyz>
        <limit>
          <effort>100</effort>
          <velocity>100</velocity>
          <lower>-10000000000000000</lower>
          <upper>10000000000000000</upper>
        </limit>
        <dynamics>
          <damping>0.035000000000000003</damping>
          <friction>0.00050000000000000001</friction>
          <spring_reference>0</spring_reference>
          <spring_stiffness>0</spring_stiffness>
        </dynamics>
      </axis>
    </joint>
    <link name='robot_summit_xl_back_right_wheel'>
      <pose relative_to='robot_summit_xl_back_right_wheel_joint'>0 0 0 0 0 0</pose>
      <inertial>
        <pose>0 0 0 0 0 0</pose>
        <mass>6.5</mass>
        <inertia>
          <ixx>0.031850000000000003</ixx>
          <ixy>0</ixy>
          <ixz>0</ixz>
          <iyy>0.039324999999999999</iyy>
          <iyz>0</iyz>
          <izz>0.031850000000000003</izz>
        </inertia>
      </inertial>
      <collision name='robot_summit_xl_back_right_wheel_collision'>
        <pose>0 0 0 1.570796326794896 0 0</pose>
        <geometry>
          <cylinder>
            <length>0.14999999999999999</length>
            <radius>0.11</radius>
          </cylinder>
        </geometry>
        <surface>
          <contact>
            <ode/>
          </contact>
          <friction>
            <ode>
              <mu>1.8999999999999999</mu>
              <mu2>1.7</mu2>
              <fdir1>1 0 0</fdir1>
            </ode>
          </friction>
        </surface>
      </collision>
      <visual name='robot_summit_xl_back_right_wheel_visual'>
        <pose>0 0 0 0 0 0</pose>
        <geometry>
          <mesh>
            <scale>1 1 1</scale>
            <uri>meshes/summit_xl/visual/rubber_wheel_right.dae</uri>
          </mesh>
        </geometry>
        <material>
          <diffuse>1 1 1 1</diffuse>
          <specular>1 1 1 1</specular>
          <pbr>
            <metal>
              <albedo_map>materials/textures/summit_xl/rubber_wheel_albedo.png</albedo_map>
              <normal_map>materials/textures/summit_xl/rubber_wheel_normal.png</normal_map>
              <roughness_map>materials/textures/summit_xl/rubber_wheel_roughness.png</roughness_map>
              <metalness_map>materials/textures/summit_xl/rubber_wheel_metalness.png</metalness_map>
            </metal>
          </pbr>
        </material>
      </visual>
    </link>
    <joint name='robot_summit_xl_front_left_wheel_joint' type='revolute'>
      <pose relative_to='robot_summit_xl_base_footprint'>0.229 0.235 0.11 0 0 0</pose>
      <parent>robot_summit_xl_base_footprint</parent>
      <child>robot_summit_xl_front_left_wheel</child>
      <axis>
        <xyz>0 1 0</xyz>
        <limit>
          <effort>100</effort>
          <velocity>100</velocity>
          <lower>-10000000000000000</lower>
          <upper>10000000000000000</upper>
        </limit>
        <dynamics>
          <damping>0.035000000000000003</damping>
          <friction>0.00050000000000000001</friction>
          <spring_reference>0</spring_reference>
          <spring_stiffness>0</spring_stiffness>
        </dynamics>
      </axis>
    </joint>
    <link name='robot_summit_xl_front_left_wheel'>
      <pose relative_to='robot_summit_xl_front_left_wheel_joint'>0 0 0 0 0 0</pose>
      <inertial>
        <pose>0 0 0 0 0 0</pose>
        <mass>6.5</mass>
        <inertia>
          <ixx>0.031850000000000003</ixx>
          <ixy>0</ixy>
          <ixz>0</ixz>
          <iyy>0.039324999999999999</iyy>
          <iyz>0</iyz>
          <izz>0.031850000000000003</izz>
        </inertia>
      </inertial>
      <collision name='robot_summit_xl_front_left_wheel_collision'>
        <pose>0 0 0 1.570796326794896 0 0</pose>
        <geometry>
          <cylinder>
            <length>0.14999999999999999</length>
            <radius>0.11</radius>
          </cylinder>
        </geometry>
        <surface>
          <contact>
            <ode/>
          </contact>
          <friction>
            <ode>
              <mu>1.8999999999999999</mu>
              <mu2>1.7</mu2>
              <fdir1>1 0 0</fdir1>
            </ode>
          </friction>
        </surface>
      </collision>
      <visual name='robot_summit_xl_front_left_wheel_visual'>
        <pose>0 0 0 0 0 0</pose>
        <geometry>
          <mesh>
            <scale>1 1 1</scale>
            <uri>meshes/summit_xl/visual/rubber_wheel_left.dae</uri>
          </mesh>
        </geometry>
        <material>
          <diffuse>1 1 1 1</diffuse>
          <specular>1 1 1 1</specular>
          <pbr>
            <metal>
              <albedo_map>materials/textures/summit_xl/rubber_wheel_albedo.png</albedo_map>
              <normal_map>materials/textures/summit_xl/rubber_wheel_normal.png</normal_map>
              <roughness_map>materials/textures/summit_xl/rubber_wheel_roughness.png</roughness_map>
              <metalness_map>materials/textures/summit_xl/rubber_wheel_metalness.png</metalness_map>
            </metal>
          </pbr>
        </material>
      </visual>
    </link>
    <joint name='robot_summit_xl_front_right_wheel_joint' type='revolute'>
      <pose relative_to='robot_summit_xl_base_footprint'>0.229 -0.235 0.11 0 0 0</pose>
      <parent>robot_summit_xl_base_footprint</parent>
      <child>robot_summit_xl_front_right_wheel</child>
      <axis>
        <xyz>0 1 0</xyz>
        <limit>
          <effort>100</effort>
          <velocity>100</velocity>
          <lower>-10000000000000000</lower>
          <upper>10000000000000000</upper>
        </limit>
        <dynamics>
          <damping>0.035000000000000003</damping>
          <friction>0.00050000000000000001</friction>
          <spring_reference>0</spring_reference>
          <spring_stiffness>0</spring_stiffness>
        </dynamics>
      </axis>
    </joint>
    <link name='robot_summit_xl_front_right_wheel'>
      <pose relative_to='robot_summit_xl_front_right_wheel_joint'>0 0 0 0 0 0</pose>
      <inertial>
        <pose>0 0 0 0 0 0</pose>
        <mass>6.5</mass>
        <inertia>
          <ixx>0.031850000000000003</ixx>
          <ixy>0</ixy>
          <ixz>0</ixz>
          <iyy>0.039324999999999999</iyy>
          <iyz>0</iyz>
          <izz>0.031850000000000003</izz>
        </inertia>
      </inertial>
      <collision name='robot_summit_xl_front_right_wheel_collision'>
        <pose>0 0 0 1.570796326794896 0 0</pose>
        <geometry>
          <cylinder>
            <length>0.14999999999999999</length>
            <radius>0.11</radius>
          </cylinder>
        </geometry>
        <surface>
          <contact>
            <ode/>
          </contact>
          <friction>
            <ode>
              <mu>1.8999999999999999</mu>
              <mu2>1.7</mu2>
              <fdir1>1 0 0</fdir1>
            </ode>
          </friction>
        </surface>
      </collision>
      <visual name='robot_summit_xl_front_right_wheel_visual'>
        <pose>0 0 0 0 0 0</pose>
        <geometry>
          <mesh>
            <scale>1 1 1</scale>
            <uri>meshes/summit_xl/visual/rubber_wheel_right.dae</uri>
          </mesh>
        </geometry>
        <material>
          <diffuse>1 1 1 1</diffuse>
          <specular>1 1 1 1</specular>
          <pbr>
            <metal>
              <albedo_map>materials/textures/summit_xl/rubber_wheel_albedo.png</albedo_map>
              <normal_map>materials/textures/summit_xl/rubber_wheel_normal.png</normal_map>
              <roughness_map>materials/textures/summit_xl/rubber_wheel_roughness.png</roughness_map>
              <metalness_map>materials/textures/summit_xl/rubber_wheel_metalness.png</metalness_map>
            </metal>
          </pbr>
        </material>
      </visual>
    </link>
    <plugin name='ignition::gazebo::systems::DiffDrive' filename='ignition-gazebo-diff-drive-system'>
      <left_joint>robot_summit_xl_front_left_wheel_joint</left_joint>
      <left_joint>robot_summit_xl_back_left_wheel_joint</left_joint>
      <right_joint>robot_summit_xl_front_right_wheel_joint</right_joint>
      <right_joint>robot_summit_xl_back_right_wheel_joint</right_joint>
      <wheel_separation>0.47</wheel_separation>
      <wheel_radius>0.11</wheel_radius>
    </plugin>
    <plugin name='ign_ros2_control::IgnitionROS2ControlPlugin' filename='ign_ros2_control-system'>
      <parameters>/home/andrej/ws/code/repos/lunalab_summit_xl_gen/install/share/lunalab_summit_xl_gen_moveit_config/config/controllers_effort.yaml</parameters>
    </plugin>
    <static>false</static>
    <plugin name='ignition::gazebo::systems::PosePublisher' filename='ignition-gazebo-pose-publisher-system'>
      <use_pose_vector_msg>true</use_pose_vector_msg>
      <publish_nested_model_pose>true</publish_nested_model_pose>
      <publish_link_pose>false</publish_link_pose>
      <publish_collision_pose>false</publish_collision_pose>
      <publish_visual_pose>false</publish_visual_pose>
    </plugin>
  </model>
</sdf>
